Workbook

Sheet DataLogger
A1: TOA5 | B1: MyDatalogger | C1: CR1000 | D1: 40327 | E1: CR1000.Std.21 | F1: Table1 | H1: חיישן רטיבות קרקע
A2: TIMESTAMP | C2: RECORD | D2: PTemp_C_Avg | E2: SlrW_Avg | F2: DriWet_C1_Avg(1) | G2: DriWet_C1_Avg(2) | H2: Res1Calib_Avg | I2: Res2Temp_Avg | J2: Res3EC_Avg | K2: RH, %
F3: Twb | G3: Tdb
A4: TS | C4: RN | D4: Deg C | E4: W/m^2 | F4: Deg C | G4: Deg C | H4: calibratedCountsVWC | I4: Deg C | J4: μS/cm
D5: Avg | E5: Avg | F5: Avg | G5: Avg | H5: VWCmineral | I5: Avg | J5: Avg
A6: 45879 | B6: 0.52083333 | C6: 0 | D6: 44.25 | E6: 685.6 | F6: 27.73 | G6: NAN | H6: 0.0906733 | I6: 37.7 | J6: 141.6 | K6: =100*((0.6108*EXP(17.27*F6/(F6+237.3)) - 0.066*(G6-F6)) / (0.6108*EXP(17.27*G6/(G6+237.3)))) -> #VALUE!
A7: 45879 | B7: 0.52777778 | C7: 1 | D7: 44.24 | E7: 776.2 | F7: 28.17 | G7: NAN | H7: 0.2826838 | I7: 37.82 | J7: 142 | K7: =100*((0.6108*EXP(17.27*F7/(F7+237.3)) - 0.066*(G7-F7)) / (0.6108*EXP(17.27*G7/(G7+237.3)))) -> #VALUE!
A8: 45879 | B8: 0.53472222 | C8: 2 | D8: 44.25 | E8: 805 | F8: 27.9 | G8: NAN | H8: 0.2124739 | I8: 37.41 | J8: 142.3 | K8: =100*((0.6108*EXP(17.27*F8/(F8+237.3)) - 0.066*(G8-F8)) / (0.6108*EXP(17.27*G8/(G8+237.3)))) -> #VALUE!
A9: 45879 | B9: 0.54166667 | C9: 3 | D9: 44.12 | E9: 811 | F9: 27.6 | G9: NAN | H9: 0.00262 | I9: 37.07 | J9: 142.4 | K9: =100*((0.6108*EXP(17.27*F9/(F9+237.3)) - 0.066*(G9-F9)) / (0.6108*EXP(17.27*G9/(G9+237.3)))) -> #VALUE!
A10: 45879 | B10: 0.54861111 | C10: 4 | D10: 43.92 | E10: 814 | F10: 27.65 | G10: NAN | H10: 0.2570824 | I10: 39.13 | J10: 146.5 | K10: =100*((0.6108*EXP(17.27*F10/(F10+237.3)) - 0.066*(G10-F10)) / (0.6108*EXP(17.27*G10/(G10+237.3)))) -> #VALUE!
A11: 45879 | B11: 0.55555556 | C11: 5 | D11: 43.81 | E11: 729 | F11: 27.81 | G11: NAN | H11: 0.2415664 | I11: 39.51 | J11: 131.9 | K11: =100*((0.6108*EXP(17.27*F11/(F11+237.3)) - 0.066*(G11-F11)) / (0.6108*EXP(17.27*G11/(G11+237.3)))) -> #VALUE!
A12: 45879 | B12: 0.5625 | C12: 6 | D12: 43.93 | E12: 722.8 | F12: 27.84 | G12: NAN | H12: 0.2555308 | I12: 39.68 | J12: 129.4 | K12: =100*((0.6108*EXP(17.27*F12/(F12+237.3)) - 0.066*(G12-F12)) / (0.6108*EXP(17.27*G12/(G12+237.3)))) -> #VALUE!
A13: 45879 | B13: 0.56944444 | C13: 7 | D13: 43.96 | E13: 762.1 | F13: 27.52 | G13: NAN | H13: 0.3071215 | I13: 39.8 | J13: 128.5 | K13: =100*((0.6108*EXP(17.27*F13/(F13+237.3)) - 0.066*(G13-F13)) / (0.6108*EXP(17.27*G13/(G13+237.3)))) -> #VALUE!
A14: 45879 | B14: 0.57638889 | C14: 8 | D14: 43.85 | E14: 709.7 | F14: 27.72 | G14: NAN | H14: 0.0076627 | I14: 38.47 | J14: 129 | K14: =100*((0.6108*EXP(17.27*F14/(F14+237.3)) - 0.066*(G14-F14)) / (0.6108*EXP(17.27*G14/(G14+237.3)))) -> #VALUE!
A15: 45879 | B15: 0.58333333 | C15: 9 | D15: 43.8 | E15: 688.2 | F15: 27.6 | G15: NAN | H15: 0.0778726 | I15: 39.8 | J15: 128.9 | K15: =100*((0.6108*EXP(17.27*F15/(F15+237.3)) - 0.066*(G15-F15)) / (0.6108*EXP(17.27*G15/(G15+237.3)))) -> #VALUE!
A16: 45879 | B16: 0.59027778 | C16: 10 | D16: 43.71 | E16: 672.7 | F16: 27.32 | G16: NAN | H16: 0.2357479 | I16: 39.69 | J16: 129.6 | K16: =100*((0.6108*EXP(17.27*F16/(F16+237.3)) - 0.066*(G16-F16)) / (0.6108*EXP(17.27*G16/(G16+237.3)))) -> #VALUE!
A17: 45879 | B17: 0.59722222 | C17: 11 | D17: 43.42 | E17: 659.3 | F17: 27.28 | G17: NAN | H17: 0.3059578 | I17: 39.54 | J17: 130.3 | K17: =100*((0.6108*EXP(17.27*F17/(F17+237.3)) - 0.066*(G17-F17)) / (0.6108*EXP(17.27*G17/(G17+237.3)))) -> #VALUE!
... A40: 45879 | B40: 0.75694444 | C40: 34 | D40: 34.99 | E40: 11.01 | F40: 24.63 | G40: NAN | H40: 0.1484704 | I40: 33.7 | J40: 149 | K40: =100*((0.6108*EXP(17.27*F40/(F40+237.3)) - 0.066*(G40-F40)) / (0.6108*EXP(17.27*G40/(G40+237.3)))) -> #VALUE!
A41: 45879 | B41: 0.76388889 | C41: 35 | D41: 34.74 | E41: 5.565 | F41: 24.79 | G41: NAN | H41: #VALUE! | I41: 31.9 | J41: 149.8 | K41: =100*((0.6108*EXP(17.27*F41/(F41+237.3)) - 0.066*(G41-F41)) / (0.6108*EXP(17.27*G41/(G41+237.3)))) -> #VALUE!
A42: 45879 | B42: 0.77083333 | C42: 36 | D42: 34.57 | E42: 2.657 | F42: 24.31 | G42: NAN | H42: 0.2539792 | I42: 33.84 | J42: 150.3 | K42: =100*((0.6108*EXP(17.27*F42/(F42+237.3)) - 0.066*(G42-F42)) / (0.6108*EXP(17.27*G42/(G42+237.3)))) -> #VALUE!
A43: 45879 | B43: 0.77777778 | C43: 37 | D43: 34.41 | E43: 0.977 | F43: 24.04 | G43: NAN | H43: #VALUE! | I43: 33.06 | J43: 151 | K43: =100*((0.6108*EXP(17.27*F43/(F43+237.3)) - 0.066*(G43-F43)) / (0.6108*EXP(17.27*G43/(G43+237.3)))) -> #VALUE!
A44: 45879 | B44: 0.78472222 | C44: 38 | D44: 34.22 | E44: 0.234 | F44: 23.81 | G44: NAN | H44: #VALUE! | I44: 32.78 | J44: 151.3 | K44: =100*((0.6108*EXP(17.27*F44/(F44+237.3)) - 0.066*(G44-F44)) / (0.6108*EXP(17.27*G44/(G44+237.3)))) -> #VALUE!
A45: 45879 | B45: 0.79166667 | C45: 39 | D45: 34.08 | E45: 0 | F45: 23.78 | G45: NAN | H45: 0.3071215 | I45: 31.71 | J45: 152.2 | K45: =100*((0.6108*EXP(17.27*F45/(F45+237.3)) - 0.066*(G45-F45)) / (0.6108*EXP(17.27*G45/(G45+237.3)))) -> #VALUE!
A46: 45879 | B46: 0.79861111 | C46: 40 | D46: 33.92 | E46: 0 | F46: 23.62 | G46: NAN | H46: 0.2900539 | I46: 31.91 | J46: 152.7 | K46: =100*((0.6108*EXP(17.27*F46/(F46+237.3)) - 0.066*(G46-F46)) / (0.6108*EXP(17.27*G46/(G46+237.3)))) -> #VALUE!
A47: 45879 | B47: 0.80555556 | C47: 41 | D47: 33.76 | E47: 0 | F47: 23.69 | G47: NAN | H47: 0.254755 | I47: 32.82 | J47: 152.9 | K47: =100*((0.6108*EXP(17.27*F47/(F47+237.3)) - 0.066*(G47-F47)) / (0.6108*EXP(17.27*G47/(G47+237.3)))) -> #VALUE!
A48: 45879 | B48: 0.8125 | C48: 42 | D48: 33.63 | E48: 0 | F48: 23.55 | G48: NAN | H48: 0.2904418 | I48: 32.63 | J48: 153.5 | K48: =100*((0.6108*EXP(17.27*F48/(F48+237.3)) - 0.066*(G48-F48)) / (0.6108*EXP(17.27*G48/(G48+237.3)))) -> #VALUE!
A49: 45879 | B49: 0.81944444 | C49: 43 | D49: 33.53 | E49: 0.003 | F49: 23.51 | G49: NAN | H49: 0.3082852 | I49: 32.45 | J49: 154.2 | K49: =100*((0.6108*EXP(17.27*F49/(F49+237.3)) - 0.066*(G49-F49)) / (0.6108*EXP(17.27*G49/(G49+237.3)))) -> #VALUE!
A50: 45879 | B50: 0.82638889 | C50: 44 | D50: 33.47 | E50: 0.017 | F50: 23.53 | G50: NAN | H50: 0.2202319 | I50: 32.25 | J50: 154.2 | K50: =100*((0.6108*EXP(17.27*F50/(F50+237.3)) - 0.066*(G50-F50)) / (0.6108*EXP(17.27*G50/(G50+237.3)))) -> #VALUE!
A51: 45879 | B51: 0.83333333 | C51: 45 | D51: 33.36 | E51: 0.02 | F51: 23.53 | G51: NAN | H51: 0.2908297 | I51: 32.06 | J51: 154.9 | K51: =100*((0.6108*EXP(17.27*F51/(F51+237.3)) - 0.066*(G51-F51)) / (0.6108*EXP(17.27*G51/(G51+237.3)))) -> #VALUE!
A52: 45879 | B52: 0.84027778 | C52: 46 | D52: 33.25 | E52: 0.116 | F52: 23.51 | G52: NAN | H52: 0.2380753 | I52: 31.89 | J52: 155.4 | K52: =100*((0.6108*EXP(17.27*F52/(F52+237.3)) - 0.066*(G52-F52)) / (0.6108*EXP(17.27*G52/(G52+237.3)))) -> #VALUE!
A53: 45879 | B53: 0.84722222 | C53: 47 | D53: 33.13 | E53: 0.043 | F53: 23.27 | G53: NAN | H53: 0.2733742 | I53: 31.74 | J53: 155.8 | K53: =100*((0.6108*EXP(17.27*F53/(F53+237.3)) - 0.066*(G53-F53)) / (0.6108*EXP(17.27*G53/(G53+237.3)))) -> #VALUE!
A54: 45879 | B54: 0.85416667 | C54: 48 | D54: 33.03 | E54: 0.132 | F54: 23.13 | G54: NAN | H54: 0.2384632 | I54: 31.57 | J54: 156.1 | K54: =100*((0.6108*EXP(17.27*F54/(F54+237.3)) - 0.066*(G54-F54)) / (0.6108*EXP(17.27*G54/(G54+237.3)))) -> #VALUE!
A55: 45879 | B55: 0.86111111 | C55: 49 | D55: 32.87 | E55: 0.066 | F55: 22.94 | G55: NAN | H55: 0.2916055 | I55: 31.39 | J55: 156.8 | K55: =100*((0.6108*EXP(17.27*F55/(F55+237.3)) - 0.066*(G55-F55)) / (0.6108*EXP(17.27*G55/(G55+237.3)))) -> #VALUE!
A56: 45879 | B56: 0.86805556 | C56: 50 | D56: 32.72 | E56: 0.069 | F56: 23.04 | G56: NAN | H56: 0.2388511 | I56: 31.24 | J56: 156.9 | K56: =100*((0.6108*EXP(17.27*F56/(F56+237.3)) - 0.066*(G56-F56)) / (0.6108*EXP(17.27*G56/(G56+237.3)))) -> #VALUE!
... A120: 45880 | B120: 0.54166667 | C120: 114 | D120: 43.49 | E120: 758.3 | F120: 28.19 | G120: NAN | H120: 0.1996732 | I120: 37.29 | J120: 248.8 | K120: =100*((0.6108*EXP(17.27*F120/(F120+237.3)) - 0.066*(G120-F120)) / (0.6108*EXP(17.27*G120/(G120+237.3)))) -> #VALUE!
A121: 45880 | B121: 0.54861111 | C121: 115 | D121: 43.61 | E121: 739.2 | F121: 28.24 | G121: NAN | H121: #VALUE! | I121: 39.08 | J121: 208.9 | K121: =100*((0.6108*EXP(17.27*F121/(F121+237.3)) - 0.066*(G121-F121)) / (0.6108*EXP(17.27*G121/(G121+237.3)))) -> #VALUE!
A122: 45880 | B122: 0.55555556 | C122: 116 | D122: 43.76 | E122: 680 | F122: 27.96 | G122: NAN | H122: 0.3707371 | I122: 39.6 | J122: 169.4 | K122: =100*((0.6108*EXP(17.27*F122/(F122+237.3)) - 0.066*(G122-F122)) / (0.6108*EXP(17.27*G122/(G122+237.3)))) -> #VALUE!
A123: 45880 | B123: 0.5625 | C123: 117 | D123: 43.68 | E123: 682.9 | F123: 27.97 | G123: NAN | H123: 0.2962603 | I123: 39.52 | J123: 168.5 | K123: =100*((0.6108*EXP(17.27*F123/(F123+237.3)) - 0.066*(G123-F123)) / (0.6108*EXP(17.27*G123/(G123+237.3)))) -> #VALUE!
A124: 45880 | B124: 0.56944444 | C124: 118 | D124: 43.53 | E124: 709.6 | F124: 28.03 | G124: NAN | H124: 0.2423422 | I124: 39.5 | J124: 169 | K124: =100*((0.6108*EXP(17.27*F124/(F124+237.3)) - 0.066*(G124-F124)) / (0.6108*EXP(17.27*G124/(G124+237.3)))) -> #VALUE!
A125: 45880 | B125: 0.57638889 | C125: 119 | D125: 43.45 | E125: 561.6 | F125: 27.64 | G125: NAN | H125: 0.188812 | I125: 39.44 | J125: 169.6 | K125: =100*((0.6108*EXP(17.27*F125/(F125+237.3)) - 0.066*(G125-F125)) / (0.6108*EXP(17.27*G125/(G125+237.3)))) -> #VALUE!
...

Sheet Clean Data_10min
A1: Station | B1: Date & Time (Summer) | C1: Global radiation (W/m^2) | D1: Relative humidity (%) | E1: Temperature (°C) | F1: Wind speed (m/s) | H1: TOA5 | I1: MyDatalogger | J1: Twb | K1: Tdb=Temp (°C) | L1: RH% | M1: Global Rad (W/m^2) | N1: Eto (mm) | P1: cleaning -> | Q1: Date | R1: Time | S1: TWB AVE | T1: TDB AVE | U1: Global Rad | W1: Eto calculation -> | X1: Penman–Monteith | Z1: e_s (T), kPa | AA1: e_a, kPa | AB1: Delta, kPa/°C) | AC1: Cd (day/night) | AD1: Rs, MJ/m2/h | AE1: Rn, MJ/m2/h (day/night)
A2: Bet Dagan Rad | B2: 10/08/2025 00:00 | C2: 0 | D2: 78 | E2: 28.1 | F2: 1.4 | H2: 45879 | I2: 0 | J2: =E2+S2 -> 24.301667 | K2: =E2+T2 -> 27.1225 | L2: =100*(22.1*10^6*10^((4.4-6.24*((J2+273.2)/1000)+9.95*((J2+273.2)/1000)^2-5.15*((J2+273.5)/1000)^3)*(1-647.3/(J2+273.2)))-101325*((K2-J2)/1514)*(1+J2/873))/(22.1*10^6*10^((4.4-6.24*((K2+273.2)/1000)+9.95*((K2+273.2)/1000)^2-5.15*((K2+273.5)/1000)^3)*(1-647.3/(K2+273.2)))) -> 79.13579 | M2: =AVERAGE(U290,U435) -> 0.0245 | N2: =(0.408*AB2*(AE2-$Y$7)+$Y$6*($Y$6/(K2+273))*$Y$8*(Z2-AA2))/(AB2+$Y$6*(1+AC2*$Y$8)) -> 1.3416041e-05 | S2: -3.7983333 | T2: -0.9775 | Z2: =0.6108*EXP(17.27*K2/(K2+237.3)) -> 3.5910437 | AA2: =(L2/100)*Z2 -> 2.8418008 | AB2: =(4098*AA2)/((K2+237.3)^2) -> 0.16655926 | AC2: =IF(M2>10,0.24,0.96) -> 0.96 | AD2: =M2*3600/1000000 -> 8.82e-05 | AE2: =IF(M2>10,(1-$Y$4)*AD2,0) -> 0
A3: Bet Dagan Rad | B3: 10/08/2025 00:10 | C3: 0 | D3: 78 | E3: 28.3 | F3: 1.9 | H3: 45879 | I3: 0.0069444444 | J3: =E3+S3 -> 24.628333 | K3: =E3+T3 -> 27.345 | L3: =100*(22.1*10^6*10^((4.4-6.24*((J3+273.2)/1000)+9.95*((J3+273.2)/1000)^2-5.15*((J3+273.5)/1000)^3)*(1-647.3/(J3+273.2)))-101325*((K3-J3)/1514)*(1+J3/873))/(22.1*10^6*10^((4.4-6.24*((K3+273.2)/1000)+9.95*((K3+273.2)/1000)^2-5.15*((K3+273.5)/1000)^3)*(1-647.3/(K3+273.2)))) -> 79.956494 | M3: =AVERAGE(U291,U436) -> 0.053 | N3: =(0.408*AB3*(AE3-$Y$7)+$Y$6*($Y$6/(K3+273))*$Y$8*(Z3-AA3))/(AB3+$Y$6*(1+AC3*$Y$8)) -> 1.2862455e-05 | S3: -3.6716667 | T3: -0.955 | X3: Cn=37dt | Y3: =37*10/60 -> 6.1666667 | Z3: =0.6108*EXP(17.27*K3/(K3+237.3)) -> 3.6381426 | AA3: =(L3/100)*Z3 -> 2.9089313 | AB3: =(4098*AA3)/((K3+237.3)^2) -> 0.17020724 | AC3: =IF(M3>10,0.24,0.96) -> 0.96 | AD3: =M3*3600/1000000 -> 0.0001908 | AE3: =IF(M3>10,(1-$Y$4)*AD3,0) -> 0
A4: Bet Dagan Rad | B4: 10/08/2025 00:20 | C4: 0 | D4: 77 | E4: 28.4 | F4: 1.8 | H4: 45879 | I4: 0.013888889 | J4: =E4+S4 -> 24.895 | K4: =E4+T4 -> 27.5875 | L4: =100*(22.1*10^6*10^((4.4-6.24*((J4+273.2)/1000)+9.95*((J4+273.2)/1000)^2-5.15*((J4+273.5)/1000)^3)*(1-647.3/(J4+273.2)))-101325*((K4-J4)/1514)*(1+J4/873))/(22.1*10^6*10^((4.4-6.24*((K4+273.2)/1000)+9.95*((K4+273.2)/1000)^2-5.15*((K4+273.5)/1000)^3)*(1-647.3/(K4+273.2)))) -> 80.221806 | M4: =AVERAGE(U292,U437) -> 0.0575 | N4: =(0.408*AB4*(AE4-$Y$7)+$Y$6*($Y$6/(K4+273))*$Y$8*(Z4-AA4))/(AB4+$Y$6*(1+AC4*$Y$8)) -> 1.2729966e-05 | S4: -3.505 | T4: -0.8125 | X4: alpha, albedo | Y4: 0.23 | Z4: =0.6108*EXP(17.27*K4/(K4+237.3)) -> 3.690087 | AA4: =(L4/100)*Z4 -> 2.9602544 | AB4: =(4098*AA4)/((K4+237.3)^2) -> 0.17289326 | AC4: =IF(M4>10,0.24,0.96) -> 0.96 | AD4: =M4*3600/1000000 -> 0.000207 | AE4: =IF(M4>10,(1-$Y$4)*AD4,0) -> 0
A5: Bet Dagan Rad | B5: 10/08/2025 00:30 | C5: 0 | D5: 77 | E5: 28.4 | F5: 1.7 | H5: 45879 | I5: 0.020833333 | J5: =E5+S5 -> 25 | K5: =E5+T5 -> 27.75 | L5: =100*(22.1*10^6*10^((4.4-6.24*((J5+273.2)/1000)+9.95*((J5+273.2)/1000)^2-5.15*((J5+273.5)/1000)^3)*(1-647.3/(J5+273.2)))-101325*((K5-J5)/1514)*(1+J5/873))/(22.1*10^6*10^((4.4-6.24*((K5+273.2)/1000)+9.95*((K5+273.2)/1000)^2-5.15*((K5+273.5)/1000)^3)*(1-647.3/(K5+273.2)))) -> 79.88661 | M5: =AVERAGE(U293,U438) -> 0.046 | N5: =(0.408*AB5*(AE5-$Y$7)+$Y$6*($Y$6/(K5+273))*$Y$8*(Z5-AA5))/(AB5+$Y$6*(1+AC5*$Y$8)) -> 1.3026639e-05 | S5: -3.4 | T5: -0.65 | X5: z, altitude, m | Y5: 0.066 | Z5: =0.6108*EXP(17.27*K5/(K5+237.3)) -> 3.7252554 | AA5: =(L5/100)*Z5 -> 2.9759802 | AB5: =(4098*AA5)/((K5+237.3)^2) -> 0.17359866 | AC5: =IF(M5>10,0.24,0.96) -> 0.96 | AD5: =M5*3600/1000000 -> 0.0001656 | AE5: =IF(M5>10,(1-$Y$4)*AD5,0) -> 0
A6: Bet Dagan Rad | B6: 10/08/2025 00:40 | C6: 0 | D6: 77 | E6: 28.3 | F6: 1.3 | H6: 45879 | I6: 0.027777778 | J6: =E6+S6 -> 25.065 | K6: =E6+T6 -> 27.6825 | L6: =100*(22.1*10^6*10^((4.4-6.24*((J6+273.2)/1000)+9.95*((J6+273.2)/1000)^2-5.15*((J6+273.5)/1000)^3)*(1-647.3/(J6+273.2)))-101325*((K6-J6)/1514)*(1+J6/873))/(22.1*10^6*10^((4.4-6.24*((K6+273.2)/1000)+9.95*((K6+273.2)/1000)^2-5.15*((K6+273.5)/1000)^3)*(1-647.3/(K6+273.2)))) -> 80.781583 | M6: =AVERAGE(U294,U439) -> 0.038 | N6: =(0.408*AB6*(AE6-$Y$7)+$Y$6*($Y$6/(K6+273))*$Y$8*(Z6-AA6))/(AB6+$Y$6*(1+AC6*$Y$8)) -> 1.2337177e-05 | S6: -3.235 | T6: -0.6175 | X6: gamma, see level pressure, kPa/°C | Y6: =0.000665*(101.3*((293-0.0065*Y5)/293)^5.26) -> 0.067363981 | Z6: =0.6108*EXP(17.27*K6/(K6+237.3)) -> 3.7106117 | AA6: =(L6/100)*Z6 -> 2.9974909 | AB6: =(4098*AA6)/((K6+237.3)^2) -> 0.17494254 | AC6: =IF(M6>10,0.24,0.96) -> 0.96 | AD6: =M6*3600/1000000 -> 0.0001368 | AE6: =IF(M6>10,(1-$Y$4)*AD6,0) -> 0
A7: Bet Dagan Rad | B7: 10/08/2025 00:50 | C7: 0 | D7: 77 | E7: 28.3 | F7: 1.2 | H7: 45879 | I7: 0.034722222 | J7: =E7+S7 -> 25.22 | K7: =E7+T7 -> 27.82 | L7: =100*(22.1*10^6*10^((4.4-6.24*((J7+273.2)/1000)+9.95*((J7+273.2)/1000)^2-5.15*((J7+273.5)/1000)^3)*(1-647.3/(J7+273.2)))-101325*((K7-J7)/1514)*(1+J7/873))/(22.1*10^6*10^((4.4-6.24*((K7+273.2)/1000)+9.95*((K7+273.2)/1000)^2-5.15*((K7+273.5)/1000)^3)*(1-647.3/(K7+273.2)))) -> 80.955665 | M7: =AVERAGE(U295,U440) -> 0.013 | N7: =(0.408*AB7*(AE7-$Y$7)+$Y$6*($Y$6/(K7+273))*$Y$8*(Z7-AA7))/(AB7+$Y$6*(1+AC7*$Y$8)) -> 1.2243134e-05 | S7: -3.08 | T7: -0.48 | X7: G, soil heat flux,W/m2 | Y7: 0 | Z7: =0.6108*EXP(17.27*K7/(K7+237.3)) -> 3.7404945 | AA7: =(L7/100)*Z7 -> 3.0281422 | AB7: =(4098*AA7)/((K7+237.3)^2) -> 0.17654818 | AC7: =IF(M7>10,0.24,0.96) -> 0.96 | AD7: =M7*3600/1000000 -> 4.68e-05 | AE7: =IF(M7>10,(1-$Y$4)*AD7,0) -> 0
A8: Bet Dagan Rad | B8: 10/08/2025 01:00 | C8: 0 | D8: 78 | E8: 28.3 | F8: 1.6 | H8: 45879 | I8: 0.041666667 | J8: =E8+S8 -> 25.251667 | K8: =E8+T8 -> 27.7775 | L8: =100*(22.1*10^6*10^((4.4-6.24*((J8+273.2)/1000)+9.95*((J8+273.2)/1000)^2-5.15*((J8+273.5)/1000)^3)*(1-647.3/(J8+273.2)))-101325*((K8-J8)/1514)*(1+J8/873))/(22.1*10^6*10^((4.4-6.24*((K8+273.2)/1000)+9.95*((K8+273.2)/1000)^2-5.15*((K8+273.5)/1000)^3)*(1-647.3/(K8+273.2)))) -> 81.457126 | M8: =AVERAGE(U296,U441) -> 0.0165 | N8: =(0.408*AB8*(AE8-$Y$7)+$Y$6*($Y$6/(K8+273))*$Y$8*(Z8-AA8))/(AB8+$Y$6*(1+AC8*$Y$8)) -> 1.1860917e-05 | S8: -3.0483333 | T8: -0.5225 | X8: u, indoor wind, m/s | Y8: 0.3 | Z8: =0.6108*EXP(17.27*K8/(K8+237.3)) -> 3.7312357 | AA8: =(L8/100)*Z8 -> 3.0393574 | AB8: =(4098*AA8)/((K8+237.3)^2) -> 0.17725888 | AC8: =IF(M8>10,0.24,0.96) -> 0.96 | AD8: =M8*3600/1000000 -> 5.94e-05 | AE8: =IF(M8>10,(1-$Y$4)*AD8,0) -> 0
A9: Bet Dagan Rad | B9: 10/08/2025 01:10 | C9: 0 | D9: 78 | E9: 28.2 | F9: 1.8 | H9: 45879 | I9: 0.048611111 | J9: =E9+S9 -> 25.051667 | K9: =E9+T9 -> 27.5425 | L9: =100*(22.1*10^6*10^((4.4-6.24*((J9+273.2)/1000)+9.95*((J9+273.2)/1000)^2-5.15*((J9+273.5)/1000)^3)*(1-647.3/(J9+273.2)))-101325*((K9-J9)/1514)*(1+J9/873))/(22.1*10^6*10^((4.4-6.24*((K9+273.2)/1000)+9.95*((K9+273.2)/1000)^2-5.15*((K9+273.5)/1000)^3)*(1-647.3/(K9+273.2)))) -> 81.616234 | M9: =AVERAGE(U297,U442) -> 0.025 | N9: =(0.408*AB9*(AE9-$Y$7)+$Y$6*($Y$6/(K9+273))*$Y$8*(Z9-AA9))/(AB9+$Y$6*(1+AC9*$Y$8)) -> 1.1686012e-05 | S9: -3.1483333 | T9: -0.6575 | Z9: =0.6108*EXP(17.27*K9/(K9+237.3)) -> 3.6803993 | AA9: =(L9/100)*Z9 -> 3.0038033 | AB9: =(4098*AA9)/((K9+237.3)^2) -> 0.17549635 | AC9: =IF(M9>10,0.24,0.96) -> 0.96 | AD9: =M9*3600/1000000 -> 9e-05 | AE9: =IF(M9>10,(1-$Y$4)*AD9,0) -> 0
A10: Bet Dagan Rad | B10: 10/08/2025 01:20 | C10: 0 | D10: 78 | E10: 28.2 | F10: 1.8 | H10: 45879 | I10: 0.055555556 | J10: =E10+S10 -> 25.17 | K10: =E10+T10 -> 27.5875 | L10: =100*(22.1*10^6*10^((4.4-6.24*((J10+273.2)/1000)+9.95*((J10+273.2)/1000)^2-5.15*((J10+273.5)/1000)^3)*(1-647.3/(J10+273.2)))-101325*((K10-J10)/1514)*(1+J10/873))/(22.1*10^6*10^((4.4-6.24*((K10+273.2)/1000)+9.95*((K10+273.2)/1000)^2-5.15*((K10+273.5)/1000)^3)*(1-647.3/(K10+273.2)))) -> 82.148494 | M10: =AVERAGE(U298,U443) -> 0.0145 | N10: =(0.408*AB10*(AE10-$Y$7)+$Y$6*($Y$6/(K10+273))*$Y$8*(Z10-AA10))/(AB10+$Y$6*(1+AC10*$Y$8)) -> 1.1309029e-05 | S10: -3.03 | T10: -0.6125 | Z10: =0.6108*EXP(17.27*K10/(K10+237.3)) -> 3.690087 | AA10: =(L10/100)*Z10 -> 3.0313509 | AB10: =(4098*AA10)/((K10+237.3)^2) -> 0.17704564 | AC10: =IF(M10>10,0.24,0.96) -> 0.96 | AD10: =M10*3600/1000000 -> 5.22e-05 | AE10: =IF(M10>10,(1-$Y$4)*AD10,0) -> 0
A11: Bet Dagan Rad | B11: 10/08/2025 01:30 | C11: 0 | D11: 79 | E11: 28.1 | F11: 1.4 | H11: 45879 | I11: 0.0625 | J11: =E11+S11 -> 24.97 | K11: =E11+T11 -> 27.3575 | L11: =100*(22.1*10^6*10^((4.4-6.24*((J11+273.2)/1000)+9.95*((J11+273.2)/1000)^2-5.15*((J11+273.5)/1000)^3)*(1-647.3/(J11+273.2)))-101325*((K11-J11)/1514)*(1+J11/873))/(22.1*10^6*10^((4.4-6.24*((K11+273.2)/1000)+9.95*((K11+273.2)/1000)^2-5.15*((K11+273.5)/1000)^3)*(1-647.3/(K11+273.2)))) -> 82.278713 | M11: =AVERAGE(U299,U444) -> 0 | N11: =(0.408*AB11*(AE11-$Y$7)+$Y$6*($Y$6/(K11+273))*$Y$8*(Z11-AA11))/(AB11+$Y$6*(1+AC11*$Y$8)) -> 1.1160528e-05 | S11: -3.13 | T11: -0.7425 | Z11: =0.6108*EXP(17.27*K11/(K11+237.3)) -> 3.6408045 | AA11: =(L11/100)*Z11 -> 2.9956071 | AB11: =(4098*AA11)/((K11+237.3)^2) -> 0.17526226 | AC11: =IF(M11>10,0.24,0.96) -> 0.96 | AD11: =M11*3600/1000000 -> 0 | AE11: =IF(M11>10,(1-$Y$4)*AD11,0) -> 0
A12: Bet Dagan Rad | B12: 10/08/2025 01:40 | C12: 0 | D12: 78 | E12: 28.1 | F12: 2 | H12: 45879 | I12: 0.069444444 | J12: =E12+S12 -> 24.918333 | K12: =E12+T12 -> 27.2875 | L12: =100*(22.1*10^6*10^((4.4-6.24*((J12+273.2)/1000)+9.95*((J12+273.2)/1000)^2-5.15*((J12+273.5)/1000)^3)*(1-647.3/(J12+273.2)))-101325*((K12-J12)/1514)*(1+J12/873))/(22.1*10^6*10^((4.4-6.24*((K12+273.2)/1000)+9.95*((K12+273.2)/1000)^2-5.15*((K12+273.5)/1000)^3)*(1-647.3/(K12+273.2)))) -> 82.383922 | M12: =AVERAGE(U300,U445) -> 0.0035 | N12: =(0.408*AB12*(AE12-$Y$7)+$Y$6*($Y$6/(K12+273))*$Y$8*(Z12-AA12))/(AB12+$Y$6*(1+AC12*$Y$8)) -> 1.1068421e-05 | S12: -3.1816667 | T12: -0.8125 | Z12: =0.6108*EXP(17.27*K12/(K12+237.3)) -> 3.6259197 | AA12: =(L12/100)*Z12 -> 2.9871749 | AB12: =(4098*AA12)/((K12+237.3)^2) -> 0.1748614 | AC12: =IF(M12>10,0.24,0.96) -> 0.96 | AD12: =M12*3600/1000000 -> 1.26e-05 | AE12: =IF(M12>10,(1-$Y$4)*AD12,0) -> 0
A13: Bet Dagan Rad | B13: 10/08/2025 01:50 | C13: 0 | D13: 78 | E13: 28.1 | F13: 1.4 | H13: 45879 | I13: 0.076388889 | J13: =E13+S13 -> 25.018333 | K13: =E13+T13 -> 27.35 | L13: =100*(22.1*10^6*10^((4.4-6.24*((J13+273.2)/1000)+9.95*((J13+273.2)/1000)^2-5.15*((J13+273.5)/1000)^3)*(1-647.3/(J13+273.2)))-101325*((K13-J13)/1514)*(1+J13/873))/(22.1*10^6*10^((4.4-6.24*((K13+273.2)/1000)+9.95*((K13+273.2)/1000)^2-5.15*((K13+273.5)/1000)^3)*(1-647.3/(K13+273.2)))) -> 82.672082 | M13: =AVERAGE(U301,U446) -> 0.008 | N13: =(0.408*AB13*(AE13-$Y$7)+$Y$6*($Y$6/(K13+273))*$Y$8*(Z13-AA13))/(AB13+$Y$6*(1+AC13*$Y$8)) -> 1.0876288e-05 | S13: -3.0816667 | T13: -0.75 | Z13: =0.6108*EXP(17.27*K13/(K13+237.3)) -> 3.6392072 | AA13: =(L13/100)*Z13 -> 3.0086084 | AB13: =(4098*AA13)/((K13+237.3)^2) -> 0.17603289 | AC13: =IF(M13>10,0.24,0.96) -> 0.96 | AD13: =M13*3600/1000000 -> 2.88e-05 | AE13: =IF(M13>10,(1-$Y$4)*AD13,0) -> 0
A14: Bet Dagan Rad | B14: 10/08/2025 02:00 | C14: 0 | D14: 79 | E14: 28 | F14: 0.8 | H14: 45879 | I14: 0.083333333 | J14: =E14+S14 -> 24.926667 | K14: =E14+T14 -> 27.2625 | L14: =100*(22.1*10^6*10^((4.4-6.24*((J14+273.2)/1000)+9.95*((J14+273.2)/1000)^2-5.15*((J14+273.5)/1000)^3)*(1-647.3/(J14+273.2)))-101325*((K14-J14)/1514)*(1+J14/873))/(22.1*10^6*10^((4.4-6.24*((K14+273.2)/1000)+9.95*((K14+273.2)/1000)^2-5.15*((K14+273.5)/1000)^3)*(1-647.3/(K14+273.2)))) -> 82.611994 | M14: =AVERAGE(U302,U447) -> 0.018 | N14: =(0.408*AB14*(AE14-$Y$7)+$Y$6*($Y$6/(K14+273))*$Y$8*(Z14-AA14))/(AB14+$Y$6*(1+AC14*$Y$8)) -> 1.0899188e-05 | S14: -3.0733333 | T14: -0.7375 | Z14: =0.6108*EXP(17.27*K14/(K14+237.3)) -> 3.6206166 | AA14: =(L14/100)*Z14 -> 2.9910636 | AB14: =(4098*AA14)/((K14+237.3)^2) -> 0.17512213 | AC14: =IF(M14>10,0.24,0.96) -> 0.96 | AD14: =M14*3600/1000000 -> 6.48e-05 | AE14: =IF(M14>10,(1-$Y$4)*AD14,0) -> 0
A15: Bet Dagan Rad | B15: 10/08/2025 02:10 | C15: 0 | D15: 79 | E15: 27.9 | F15: 1.4 | H15: 45879 | I15: 0.090277778 | J15: =E15+S15 -> 24.981667 | K15: =E15+T15 -> 27.39 | L15: =100*(22.1*10^6*10^((4.4-6.24*((J15+273.2)/1000)+9.95*((J15+273.2)/1000)^2-5.15*((J15+273.5)/1000)^3)*(1-647.3/(J15+273.2)))-101325*((K15-J15)/1514)*(1+J15/873))/(22.1*10^6*10^((4.4-6.24*((K15+273.2)/1000)+9.95*((K15+273.2)/1000)^2-5.15*((K15+273.5)/1000)^3)*(1-647.3/(K15+273.2)))) -> 82.14281 | M15: =AVERAGE(U303,U448) -> 0.0285 | N15: =(0.408*AB15*(AE15-$Y$7)+$Y$6*($Y$6/(K15+273))*$Y$8*(Z15-AA15))/(AB15+$Y$6*(1+AC15*$Y$8)) -> 1.1266281e-05 | S15: -2.9183333 | T15: -0.51 | Z15: =0.6108*EXP(17.27*K15/(K15+237.3)) -> 3.6477334 | AA15: =(L15/100)*Z15 -> 2.9963507 | AB15: =(4098*AA15)/((K15+237.3)^2) -> 0.17526271 | AC15: =IF(M15>10,0.24,0.96) -> 0.96 | AD15: =M15*3600/1000000 -> 0.0001026 | AE15: =IF(M15>10,(1-$Y$4)*AD15,0) -> 0
A16: Bet Dagan Rad | B16: 10/08/2025 02:20 | C16: 0 | D16: 79 | E16: 27.8 | F16: 0.8 | H16: 45879 | I16: 0.097222222 | J16: =E16+S16 -> 24.936667 | K16: =E16+T16 -> 27.315 | L16: =100*(22.1*10^6*10^((4.4-6.24*((J16+273.2)/1000)+9.95*((J16+273.2)/1000)^2-5.15*((J16+273.5)/1000)^3)*(1-647.3/(J16+273.2)))-101325*((K16-J16)/1514)*(1+J16/873))/(22.1*10^6*10^((4.4-6.24*((K16+273.2)/1000)+9.95*((K16+273.2)/1000)^2-5.15*((K16+273.5)/1000)^3)*(1-647.3/(K16+273.2)))) -> 82.328612 | M16: =AVERAGE(U304,U449) -> 0 | N16: =(0.408*AB16*(AE16-$Y$7)+$Y$6*($Y$6/(K16+273))*$Y$8*(Z16-AA16))/(AB16+$Y$6*(1+AC16*$Y$8)) -> 1.1114615e-05 | S16: -2.8633333 | T16: -0.485 | X16: https://www.fao.org/4/x0490e/x0490e06.htm | Z16: =0.6108*EXP(17.27*K16/(K16+237.3)) -> 3.631761 | AA16: =(L16/100)*Z16 -> 2.9899784 | AB16: =(4098*AA16)/((K16+237.3)^2) -> 0.17498914 | AC16: =IF(M16>10,0.24,0.96) -> 0.96 | AD16: =M16*3600/1000000 -> 0 | AE16: =IF(M16>10,(1-$Y$4)*AD16,0) -> 0
A17: Bet Dagan Rad | B17: 10/08/2025 02:30 | C17: 0 | D17: 80 | E17: 27.7 | F17: 1.3 | H17: 45879 | I17: 0.10416667 | J17: =E17+S17 -> 24.84 | K17: =E17+T17 -> 27.23 | L17: =100*(22.1*10^6*10^((4.4-6.24*((J17+273.2)/1000)+9.95*((J17+273.2)/1000)^2-5.15*((J17+273.5)/1000)^3)*(1-647.3/(J17+273.2)))-101325*((K17-J17)/1514)*(1+J17/873))/(22.1*10^6*10^((4.4-6.24*((K17+273.2)/1000)+9.95*((K17+273.2)/1000)^2-5.15*((K17+273.5)/1000)^3)*(1-647.3/(K17+273.2)))) -> 82.215532 | M17: =AVERAGE(U305,U450) -> 0 | N17: =(0.408*AB17*(AE17-$Y$7)+$Y$6*($Y$6/(K17+273))*$Y$8*(Z17-AA17))/(AB17+$Y$6*(1+AC17*$Y$8)) -> 1.1175889e-05 | S17: -2.86 | T17: -0.47 | Z17: =0.6108*EXP(17.27*K17/(K17+237.3)) -> 3.6137326 | AA17: =(L17/100)*Z17 -> 2.9710495 | AB17: =(4098*AA17)/((K17+237.3)^2) -> 0.17399308 | AC17: =IF(M17>10,0.24,0.96) -> 0.96 | AD17: =M17*3600/1000000 -> 0 | AE17: =IF(M17>10,(1-$Y$4)*AD17,0) -> 0
A18: Bet Dagan Rad | B18: 10/08/2025 02:40 | C18: 0 | D18: 80 | E18: 27.7 | F18: 1.3 | H18: 45879 | I18: 0.11111111 | J18: =E18+S18 -> 24.828333 | K18: =E18+T18 -> 27.17 | L18: =100*(22.1*10^6*10^((4.4-6.24*((J18+273.2)/1000)+9.95*((J18+273.2)/1000)^2-5.15*((J18+273.5)/1000)^3)*(1-647.3/(J18+273.2)))-101325*((K18-J18)/1514)*(1+J18/873))/(22.1*10^6*10^((4.4-6.24*((K18+273.2)/1000)+9.95*((K18+273.2)/1000)^2-5.15*((K18+273.5)/1000)^3)*(1-647.3/(K18+273.2)))) -> 82.538038 | M18: =AVERAGE(U306,U451) -> 0.003 | N18: =(0.408*AB18*(AE18-$Y$7)+$Y$6*($Y$6/(K18+273))*$Y$8*(Z18-AA18))/(AB18+$Y$6*(1+AC18*$Y$8)) -> 1.0930678e-05 | S18: -2.8716667 | T18: -0.53 | Z18: =0.6108*EXP(17.27*K18/(K18+237.3)) -> 3.6010537 | AA18: =(L18/100)*Z18 -> 2.9722391 | AB18: =(4098*AA18)/((K18+237.3)^2) -> 0.17414173 | AC18: =IF(M18>10,0.24,0.96) -> 0.96 | AD18: =M18*3600/1000000 -> 1.08e-05 | AE18: =IF(M18>10,(1-$Y$4)*AD18,0) -> 0
A19: Bet Dagan Rad | B19: 10/08/2025 02:50 | C19: 0 | D19: 80 | E19: 27.5 | F19: 1.2 | H19: 45879 | I19: 0.11805556 | J19: =E19+S19 -> 24.668333 | K19: =E19+T19 -> 26.955 | L19: =100*(22.1*10^6*10^((4.4-6.24*((J19+273.2)/1000)+9.95*((J19+273.2)/1000)^2-5.15*((J19+273.5)/1000)^3)*(1-647.3/(J19+273.2)))-101325*((K19-J19)/1514)*(1+J19/873))/(22.1*10^6*10^((4.4-6.24*((K19+273.2)/1000)+9.95*((K19+273.2)/1000)^2-5.15*((K19+273.5)/1000)^3)*(1-647.3/(K19+273.2)))) -> 82.855932 | M19: =AVERAGE(U307,U452) -> 0.008 | N19: =(0.408*AB19*(AE19-$Y$7)+$Y$6*($Y$6/(K19+273))*$Y$8*(Z19-AA19))/(AB19+$Y$6*(1+AC19*$Y$8)) -> 1.0655408e-05 | S19: -2.8316667 | T19: -0.545 | Z19: =0.6108*EXP(17.27*K19/(K19+237.3)) -> 3.5559384 | AA19: =(L19/100)*Z19 -> 2.9463059 | AB19: =(4098*AA19)/((K19+237.3)^2) -> 0.17290333 | AC19: =IF(M19>10,0.24,0.96) -> 0.96 | AD19: =M19*3600/1000000 -> 2.88e-05 | AE19: =IF(M19>10,(1-$Y$4)*AD19,0) -> 0
A20: Bet Dagan Rad | B20: 10/08/2025 03:00 | C20: 0 | D20: 80 | E20: 27.3 | F20: 0.9 | H20: 45879 | I20: 0.125 | J20: =E20+S20 -> 24.285 | K20: =E20+T20 -> 26.55 | L20: =100*(22.1*10^6*10^((4.4-6.24*((J20+273.2)/1000)+9.95*((J20+273.2)/1000)^2-5.15*((J20+273.5)/1000)^3)*(1-647.3/(J20+273.2)))-101325*((K20-J20)/1514)*(1+J20/873))/(22.1*10^6*10^((4.4-6.24*((K20+273.2)/1000)+9.95*((K20+273.2)/1000)^2-5.15*((K20+273.5)/1000)^3)*(1-647.3/(K20+273.2)))) -> 82.870387 | M20: =AVERAGE(U308,U453) -> 0.014 | N20: =(0.408*AB20*(AE20-$Y$7)+$Y$6*($Y$6/(K20+273))*$Y$8*(Z20-AA20))/(AB20+$Y$6*(1+AC20*$Y$8)) -> 1.0553053e-05 | S20: -3.015 | T20: -0.75 | Z20: =0.6108*EXP(17.27*K20/(K20+237.3)) -> 3.4722895 | AA20: =(L20/100)*Z20 -> 2.8774998 | AB20: =(4098*AA20)/((K20+237.3)^2) -> 0.16938426 | AC20: =IF(M20>10,0.24,0.96) -> 0.96 | AD20: =M20*3600/1000000 -> 5.04e-05 | AE20: =IF(M20>10,(1-$Y$4)*AD20,0) -> 0
A21: Bet Dagan Rad | B21: 10/08/2025 03:10 | C21: 0 | D21: 81 | E21: 27.1 | F21: 0.7 | H21: 45879 | I21: 0.13194444 | J21: =E21+S21 -> 24.101667 | K21: =E21+T21 -> 26.275 | L21: =100*(22.1*10^6*10^((4.4-6.24*((J21+273.2)/1000)+9.95*((J21+273.2)/1000)^2-5.15*((J21+273.5)/1000)^3)*(1-647.3/(J21+273.2)))-101325*((K21-J21)/1514)*(1+J21/873))/(22.1*10^6*10^((4.4-6.24*((K21+273.2)/1000)+9.95*((K21+273.2)/1000)^2-5.15*((K21+273.5)/1000)^3)*(1-647.3/(K21+273.2)))) -> 83.441335 | M21: =AVERAGE(U309,U454) -> 0.0145 | N21: =(0.408*AB21*(AE21-$Y$7)+$Y$6*($Y$6/(K21+273))*$Y$8*(Z21-AA21))/(AB21+$Y$6*(1+AC21*$Y$8)) -> 1.0094794e-05 | S21: -2.9983333 | T21: -0.825 | Z21: =0.6108*EXP(17.27*K21/(K21+237.3)) -> 3.4164729 | AA21: =(L21/100)*Z21 -> 2.8507506 | AB21: =(4098*AA21)/((K21+237.3)^2) -> 0.16816002 | AC21: =IF(M21>10,0.24,0.96) -> 0.96 | AD21: =M21*3600/1000000 -> 5.22e-05 | AE21: =IF(M21>10,(1-$Y$4)*AD21,0) -> 0
A22: Bet Dagan Rad | B22: 10/08/2025 03:20 | C22: 0 | D22: 82 | E22: 27 | F22: 0.6 | H22: 45879 | I22: 0.13888889 | J22: =E22+S22 -> 23.995 | K22: =E22+T22 -> 26.16 | L22: =100*(22.1*10^6*10^((4.4-6.24*((J22+273.2)/1000)+9.95*((J22+273.2)/1000)^2-5.15*((J22+273.5)/1000)^3)*(1-647.3/(J22+273.2)))-101325*((K22-J22)/1514)*(1+J22/873))/(22.1*10^6*10^((4.4-6.24*((K22+273.2)/1000)+9.95*((K22+273.2)/1000)^2-5.15*((K22+273.5)/1000)^3)*(1-647.3/(K22+273.2)))) -> 83.462826 | M22: =AVERAGE(U310,U455) -> 0.01 | N22: =(0.408*AB22*(AE22-$Y$7)+$Y$6*($Y$6/(K22+273))*$Y$8*(Z22-AA22))/(AB22+$Y$6*(1+AC22*$Y$8)) -> 1.0054762e-05 | S22: -3.005 | T22: -0.84 | Z22: =0.6108*EXP(17.27*K22/(K22+237.3)) -> 3.3933643 | AA22: =(L22/100)*Z22 -> 2.8321978 | AB22: =(4098*AA22)/((K22+237.3)^2) -> 0.16721151 | AC22: =IF(M22>10,0.24,0.96) -> 0.96 | AD22: =M22*3600/1000000 -> 3.6e-05 | AE22: =IF(M22>10,(1-$Y$4)*AD22,0) -> 0
A23: Bet Dagan Rad | B23: 10/08/2025 03:30 | C23: 0 | D23: 82 | E23: 26.8 | F23: 0.7 | H23: 45879 | I23: 0.14583333 | J23: =E23+S23 -> 23.805 | K23: =E23+T23 -> 25.94 | L23: =100*(22.1*10^6*10^((4.4-6.24*((J23+273.2)/1000)+9.95*((J23+273.2)/1000)^2-5.15*((J23+273.5)/1000)^3)*(1-647.3/(J23+273.2)))-101325*((K23-J23)/1514)*(1+J23/873))/(22.1*10^6*10^((4.4-6.24*((K23+273.2)/1000)+9.95*((K23+273.2)/1000)^2-5.15*((K23+273.5)/1000)^3)*(1-647.3/(K23+273.2)))) -> 83.607691 | M23: =AVERAGE(U311,U456) -> 0 | N23: =(0.408*AB23*(AE23-$Y$7)+$Y$6*($Y$6/(K23+273))*$Y$8*(Z23-AA23))/(AB23+$Y$6*(1+AC23*$Y$8)) -> 9.9074815e-06 | S23: -2.995 | T23: -0.86 | Z23: =0.6108*EXP(17.27*K23/(K23+237.3)) -> 3.3495358 | AA23: =(L23/100)*Z23 -> 2.8004696 | AB23: =(4098*AA23)/((K23+237.3)^2) -> 0.16561476 | AC23: =IF(M23>10,0.24,0.96) -> 0.96 | AD23: =M23*3600/1000000 -> 0 | AE23: =IF(M23>10,(1-$Y$4)*AD23,0) -> 0
A24: Bet Dagan Rad | B24: 10/08/2025 03:40 | C24: 0 | D24: 83 | E24: 26.6 | F24: 1.2 | H24: 45879 | I24: 0.15277778 | J24: =E24+S24 -> 23.545 | K24: =E24+T24 -> 25.605 | L24: =100*(22.1*10^6*10^((4.4-6.24*((J24+273.2)/1000)+9.95*((J24+273.2)/1000)^2-5.15*((J24+273.5)/1000)^3)*(1-647.3/(J24+273.2)))-101325*((K24-J24)/1514)*(1+J24/873))/(22.1*10^6*10^((4.4-6.24*((K24+273.2)/1000)+9.95*((K24+273.2)/1000)^2-5.15*((K24+273.5)/1000)^3)*(1-647.3/(K24+273.2)))) -> 84.049086 | M24: =AVERAGE(U312,U457) -> 0.0165 | N24: =(0.408*AB24*(AE24-$Y$7)+$Y$6*($Y$6/(K24+273))*$Y$8*(Z24-AA24))/(AB24+$Y$6*(1+AC24*$Y$8)) -> 9.5367488e-06 | S24: -3.055 | T24: -0.995 | Z24: =0.6108*EXP(17.27*K24/(K24+237.3)) -> 3.2837445 | AA24: =(L24/100)*Z24 -> 2.7599573 | AB24: =(4098*AA24)/((K24+237.3)^2) -> 0.16363516 | AC24: =IF(M24>10,0.24,0.96) -> 0.96 | AD24: =M24*3600/1000000 -> 5.94e-05 | AE24: =IF(M24>10,(1-$Y$4)*AD24,0) -> 0
A25: Bet Dagan Rad | B25: 10/08/2025 03:50 | C25: 0 | D25: 83 | E25: 26.5 | F25: 1.2 | H25: 45879 | I25: 0.15972222 | J25: =E25+S25 -> 23.441667 | K25: =E25+T25 -> 25.4725 | L25: =100*(22.1*10^6*10^((4.4-6.24*((J25+273.2)/1000)+9.95*((J25+273.2)/1000)^2-5.15*((J25+273.5)/1000)^3)*(1-647.3/(J25+273.2)))-101325*((K25-J25)/1514)*(1+J25/873))/(22.1*10^6*10^((4.4-6.24*((K25+273.2)/1000)+9.95*((K25+273.2)/1000)^2-5.15*((K25+273.5)/1000)^3)*(1-647.3/(K25+273.2)))) -> 84.22204 | M25: =AVERAGE(U313,U458) -> 0.0015 | N25: =(0.408*AB25*(AE25-$Y$7)+$Y$6*($Y$6/(K25+273))*$Y$8*(Z25-AA25))/(AB25+$Y$6*(1+AC25*$Y$8)) -> 9.3930115e-06 | S25: -3.0583333 | T25: -1.0275 | Z25: =0.6108*EXP(17.27*K25/(K25+237.3)) -> 3.2580352 | AA25: =(L25/100)*Z25 -> 2.7439837 | AB25: =(4098*AA25)/((K25+237.3)^2) -> 0.16285221 | AC25: =IF(M25>10,0.24,0.96) -> 0.96 | AD25: =M25*3600/1000000 -> 5.4e-06 | AE25: =IF(M25>10,(1-$Y$4)*AD25,0) -> 0
A26: Bet Dagan Rad | B26: 10/08/2025 04:00 | C26: 0 | D26: 83 | E26: 26.5 | F26: 0.5 | H26: 45879 | I26: 0.16666667 | J26: =E26+S26 -> 23.493333 | K26: =E26+T26 -> 25.5775 | L26: =100*(22.1*10^6*10^((4.4-6.24*((J26+273.2)/1000)+9.95*((J26+273.2)/1000)^2-5.15*((J26+273.5)/1000)^3)*(1-647.3/(J26+273.2)))-101325*((K26-J26)/1514)*(1+J26/873))/(22.1*10^6*10^((4.4-6.24*((K26+273.2)/1000)+9.95*((K26+273.2)/1000)^2-5.15*((K26+273.5)/1000)^3)*(1-647.3/(K26+273.2)))) -> 83.859984 | M26: =AVERAGE(U314,U459) -> 0.005 | N26: =(0.408*AB26*(AE26-$Y$7)+$Y$6*($Y$6/(K26+273))*$Y$8*(Z26-AA26))/(AB26+$Y$6*(1+AC26*$Y$8)) -> 9.658119e-06 | S26: -3.0066667 | T26: -0.9225 | Z26: =0.6108*EXP(17.27*K26/(K26+237.3)) -> 3.2783941 | AA26: =(L26/100)*Z26 -> 2.7492608 | AB26: =(4098*AA26)/((K26+237.3)^2) -> 0.16303508 | AC26: =IF(M26>10,0.24,0.96) -> 0.96 | AD26: =M26*3600/1000000 -> 1.8e-05 | AE26: =IF(M26>10,(1-$Y$4)*AD26,0) -> 0
A27: Bet Dagan Rad | B27: 10/08/2025 04:10 | C27: 0 | D27: 83 | E27: 26.3 | F27: 0.6 | H27: 45879 | I27: 0.17361111 | J27: =E27+S27 -> 23.355 | K27: =E27+T27 -> 25.42 | L27: =100*(22.1*10^6*10^((4.4-6.24*((J27+273.2)/1000)+9.95*((J27+273.2)/1000)^2-5.15*((J27+273.5)/1000)^3)*(1-647.3/(J27+273.2)))-101325*((K27-J27)/1514)*(1+J27/873))/(22.1*10^6*10^((4.4-6.24*((K27+273.2)/1000)+9.95*((K27+273.2)/1000)^2-5.15*((K27+273.5)/1000)^3)*(1-647.3/(K27+273.2)))) -> 83.949113 | M27: =AVERAGE(U315,U460) -> 0.003 | N27: =(0.408*AB27*(AE27-$Y$7)+$Y$6*($Y$6/(K27+273))*$Y$8*(Z27-AA27))/(AB27+$Y$6*(1+AC27*$Y$8)) -> 9.5645305e-06 | S27: -2.945 | T27: -0.88 | Z27: =0.6108*EXP(17.27*K27/(K27+237.3)) -> 3.2478971 | AA27: =(L27/100)*Z27 -> 2.7265808 | AB27: =(4098*AA27)/((K27+237.3)^2) -> 0.16188405 | AC27: =IF(M27>10,0.24,0.96) -> 0.96 | AD27: =M27*3600/1000000 -> 1.08e-05 | AE27: =IF(M27>10,(1-$Y$4)*AD27,0) -> 0
A28: Bet Dagan Rad | B28: 10/08/2025 04:20 | C28: 0 | D28: 83 | E28: 26.2 | F28: 1 | H28: 45879 | I28: 0.18055556 | J28: =E28+S28 -> 23.218333 | K28: =E28+T28 -> 25.3375 | L28: =100*(22.1*10^6*10^((4.4-6.24*((J28+273.2)/1000)+9.95*((J28+273.2)/1000)^2-5.15*((J28+273.5)/1000)^3)*(1-647.3/(J28+273.2)))-101325*((K28-J28)/1514)*(1+J28/873))/(22.1*10^6*10^((4.4-6.24*((K28+273.2)/1000)+9.95*((K28+273.2)/1000)^2-5.15*((K28+273.5)/1000)^3)*(1-647.3/(K28+273.2)))) -> 83.516085 | M28: =AVERAGE(U316,U461) -> 0.0065 | N28: =(0.408*AB28*(AE28-$Y$7)+$Y$6*($Y$6/(K28+273))*$Y$8*(Z28-AA28))/(AB28+$Y$6*(1+AC28*$Y$8)) -> 9.8374544e-06 | S28: -2.9816667 | T28: -0.8625 | Z28: =0.6108*EXP(17.27*K28/(K28+237.3)) -> 3.2320214 | AA28: =(L28/100)*Z28 -> 2.6992578 | AB28: =(4098*AA28)/((K28+237.3)^2) -> 0.16036251 | AC28: =IF(M28>10,0.24,0.96) -> 0.96 | AD28: =M28*3600/1000000 -> 2.34e-05 | AE28: =IF(M28>10,(1-$Y$4)*AD28,0) -> 0
... A76: Bet Dagan Rad | B76: 10/08/2025 12:20 | C76: 913 | D76: 54 | E76: 34.4 | F76: 3.7 | H76: 45879 | I76: 0.51388889 | J76: =E76+S76 -> 28.331667 | K76: =E76+T76 -> 36.972 | L76: =100*(22.1*10^6*10^((4.4-6.24*((J76+273.2)/1000)+9.95*((J76+273.2)/1000)^2-5.15*((J76+273.5)/1000)^3)*(1-647.3/(J76+273.2)))-101325*((K76-J76)/1514)*(1+J76/873))/(22.1*10^6*10^((4.4-6.24*((K76+273.2)/1000)+9.95*((K76+273.2)/1000)^2-5.15*((K76+273.5)/1000)^3)*(1-647.3/(K76+273.2)))) -> 51.857247 | M76: =AVERAGE(U364,U509) -> 686.55 | N76: =(0.408*AB76*(AE76-$Y$7)+$Y$6*($Y$6/(K76+273))*$Y$8*(Z76-AA76))/(AB76+$Y$6*(1+AC76*$Y$8)) -> 0.55152246 | S76: -6.0683333 | T76: 2.572 | Z76: =0.6108*EXP(17.27*K76/(K76+237.3)) -> 6.2652517 | AA76: =(L76/100)*Z76 -> 3.248987 | AB76: =(4098*AA76)/((K76+237.3)^2) -> 0.17699336 | AC76: =IF(M76>10,0.24,0.96) -> 0.24 | AD76: =M76*3600/1000000 -> 2.47158 | AE76: =IF(M76>10,(1-$Y$4)*AD76,0) -> 1.9031166
A77: Bet Dagan Rad | B77: 10/08/2025 12:30 | C77: 919 | D77: 53 | E77: 34.8 | F77: 3.5 | H77: 45879 | I77: 0.52083333 | J77: 27.73 | K77: =E77+T77 -> 37.244 | L77: =100*(22.1*10^6*10^((4.4-6.24*((J77+273.2)/1000)+9.95*((J77+273.2)/1000)^2-5.15*((J77+273.5)/1000)^3)*(1-647.3/(J77+273.2)))-101325*((K77-J77)/1514)*(1+J77/873))/(22.1*10^6*10^((4.4-6.24*((K77+273.2)/1000)+9.95*((K77+273.2)/1000)^2-5.15*((K77+273.5)/1000)^3)*(1-647.3/(K77+273.2)))) -> 48.056026 | M77: =U77 -> 685.6 | N77: =(0.408*AB77*(AE77-$Y$7)+$Y$6*($Y$6/(K77+273))*$Y$8*(Z77-AA77))/(AB77+$Y$6*(1+AC77*$Y$8)) -> 0.54053178 | Q77: 45879 | R77: 0.52083333 | T77: 2.444 | U77: 685.6 | Z77: =0.6108*EXP(17.27*K77/(K77+237.3)) -> 6.3586895 | AA77: =(L77/100)*Z77 -> 3.0557334 | AB77: =(4098*AA77)/((K77+237.3)^2) -> 0.16613591 | AC77: =IF(M77>10,0.24,0.96) -> 0.24 | AD77: =M77*3600/1000000 -> 2.46816 | AE77: =IF(M77>10,(1-$Y$4)*AD77,0) -> 1.9004832
A78: Bet Dagan Rad | B78: 10/08/2025 12:40 | C78: 924 | D78: 52 | E78: 34.8 | F78: 3.9 | H78: 45879 | I78: 0.52777778 | J78: 28.17 | K78: =E78+T78 -> 37.196 | L78: =100*(22.1*10^6*10^((4.4-6.24*((J78+273.2)/1000)+9.95*((J78+273.2)/1000)^2-5.15*((J78+273.5)/1000)^3)*(1-647.3/(J78+273.2)))-101325*((K78-J78)/1514)*(1+J78/873))/(22.1*10^6*10^((4.4-6.24*((K78+273.2)/1000)+9.95*((K78+273.2)/1000)^2-5.15*((K78+273.5)/1000)^3)*(1-647.3/(K78+273.2)))) -> 50.237303 | M78: =U78 -> 776.2 | N78: =(0.408*AB78*(AE78-$Y$7)+$Y$6*($Y$6/(K78+273))*$Y$8*(Z78-AA78))/(AB78+$Y$6*(1+AC78*$Y$8)) -> 0.61969396 | Q78: 45879 | R78: 0.52777778 | T78: 2.396 | U78: 776.2 | Z78: =0.6108*EXP(17.27*K78/(K78+237.3)) -> 6.3421133 | AA78: =(L78/100)*Z78 -> 3.1861066 | AB78: =(4098*AA78)/((K78+237.3)^2) -> 0.1732847 | AC78: =IF(M78>10,0.24,0.96) -> 0.24 | AD78: =M78*3600/1000000 -> 2.79432 | AE78: =IF(M78>10,(1-$Y$4)*AD78,0) -> 2.1516264
A79: Bet Dagan Rad | B79: 10/08/2025 12:50 | C79: 925 | D79: 52 | E79: 34.8 | F79: 3.7 | H79: 45879 | I79: 0.53472222 | J79: 27.9 | K79: =E79+T79 -> 37.348 | L79: =100*(22.1*10^6*10^((4.4-6.24*((J79+273.2)/1000)+9.95*((J79+273.2)/1000)^2-5.15*((J79+273.5)/1000)^3)*(1-647.3/(J79+273.2)))-101325*((K79-J79)/1514)*(1+J79/873))/(22.1*10^6*10^((4.4-6.24*((K79+273.2)/1000)+9.95*((K79+273.2)/1000)^2-5.15*((K79+273.5)/1000)^3)*(1-647.3/(K79+273.2)))) -> 48.434931 | M79: =U79 -> 805 | N79: =(0.408*AB79*(AE79-$Y$7)+$Y$6*($Y$6/(K79+273))*$Y$8*(Z79-AA79))/(AB79+$Y$6*(1+AC79*$Y$8)) -> 0.63710129 | Q79: 45879 | R79: 0.53472222 | T79: 2.548 | U79: 805 | Z79: =0.6108*EXP(17.27*K79/(K79+237.3)) -> 6.3947333 | AA79: =(L79/100)*Z79 -> 3.0972846 | AB79: =(4098*AA79)/((K79+237.3)^2) -> 0.16826748 | AC79: =IF(M79>10,0.24,0.96) -> 0.24 | AD79: =M79*3600/1000000 -> 2.898 | AE79: =IF(M79>10,(1-$Y$4)*AD79,0) -> 2.23146
A80: Bet Dagan Rad | B80: 10/08/2025 13:00 | C80: 925 | D80: 51 | E80: 35.1 | F80: 4.2 | H80: 45879 | I80: 0.54166667 | J80: 27.6 | K80: =E80+T80 -> 37.18 | L80: =100*(22.1*10^6*10^((4.4-6.24*((J80+273.2)/1000)+9.95*((J80+273.2)/1000)^2-5.15*((J80+273.5)/1000)^3)*(1-647.3/(J80+273.2)))-101325*((K80-J80)/1514)*(1+J80/873))/(22.1*10^6*10^((4.4-6.24*((K80+273.2)/1000)+9.95*((K80+273.2)/1000)^2-5.15*((K80+273.5)/1000)^3)*(1-647.3/(K80+273.2)))) -> 47.708438 | M80: =U80 -> 811 | N80: =(0.408*AB80*(AE80-$Y$7)+$Y$6*($Y$6/(K80+273))*$Y$8*(Z80-AA80))/(AB80+$Y$6*(1+AC80*$Y$8)) -> 0.63739353 | Q80: 45879 | R80: 0.54166667 | T80: 2.08 | U80: 811 | Z80: =0.6108*EXP(17.27*K80/(K80+237.3)) -> 6.3365962 | AA80: =(L80/100)*Z80 -> 3.0230911 | AB80: =(4098*AA80)/((K80+237.3)^2) -> 0.16443784 | AC80: =IF(M80>10,0.24,0.96) -> 0.24 | AD80: =M80*3600/1000000 -> 2.9196 | AE80: =IF(M80>10,(1-$Y$4)*AD80,0) -> 2.248092
A81: Bet Dagan Rad | B81: 10/08/2025 13:10 | C81: 919 | D81: 51 | E81: 35.2 | F81: 4 | H81: 45879 | I81: 0.54861111 | J81: 27.65 | K81: =E81+T81 -> 37.638 | L81: =100*(22.1*10^6*10^((4.4-6.24*((J81+273.2)/1000)+9.95*((J81+273.2)/1000)^2-5.15*((J81+273.5)/1000)^3)*(1-647.3/(J81+273.2)))-101325*((K81-J81)/1514)*(1+J81/873))/(22.1*10^6*10^((4.4-6.24*((K81+273.2)/1000)+9.95*((K81+273.2)/1000)^2-5.15*((K81+273.5)/1000)^3)*(1-647.3/(K81+273.2)))) -> 46.263516 | M81: =U81 -> 814 | N81: =(0.408*AB81*(AE81-$Y$7)+$Y$6*($Y$6/(K81+273))*$Y$8*(Z81-AA81))/(AB81+$Y$6*(1+AC81*$Y$8)) -> 0.63795231 | Q81: 45879 | R81: 0.54861111 | T81: 2.438 | U81: 814 | Z81: =0.6108*EXP(17.27*K81/(K81+237.3)) -> 6.4961761 | AA81: =(L81/100)*Z81 -> 3.0053595 | AB81: =(4098*AA81)/((K81+237.3)^2) -> 0.16292917 | AC81: =IF(M81>10,0.24,0.96) -> 0.24 | AD81: =M81*3600/1000000 -> 2.9304 | AE81: =IF(M81>10,(1-$Y$4)*AD81,0) -> 2.256408
A82: Bet Dagan Rad | B82: 10/08/2025 13:20 | C82: 915 | D82: 51 | E82: 34.9 | F82: 4.3 | H82: 45879 | I82: 0.55555556 | J82: 27.81 | K82: =E82+T82 -> 36.948 | L82: =100*(22.1*10^6*10^((4.4-6.24*((J82+273.2)/1000)+9.95*((J82+273.2)/1000)^2-5.15*((J82+273.5)/1000)^3)*(1-647.3/(J82+273.2)))-101325*((K82-J82)/1514)*(1+J82/873))/(22.1*10^6*10^((4.4-6.24*((K82+273.2)/1000)+9.95*((K82+273.2)/1000)^2-5.15*((K82+273.5)/1000)^3)*(1-647.3/(K82+273.2)))) -> 49.533472 | M82: =U82 -> 729 | N82: =(0.408*AB82*(AE82-$Y$7)+$Y$6*($Y$6/(K82+273))*$Y$8*(Z82-AA82))/(AB82+$Y$6*(1+AC82*$Y$8)) -> 0.57757519 | Q82: 45879 | R82: 0.55555556 | T82: 2.048 | U82: 729 | Z82: =0.6108*EXP(17.27*K82/(K82+237.3)) -> 6.2570645 | AA82: =(L82/100)*Z82 -> 3.0993413 | AB82: =(4098*AA82)/((K82+237.3)^2) -> 0.16887075 | AC82: =IF(M82>10,0.24,0.96) -> 0.24 | AD82: =M82*3600/1000000 -> 2.6244 | AE82: =IF(M82>10,(1-$Y$4)*AD82,0) -> 2.020788
A83: Bet Dagan Rad | B83: 10/08/2025 13:30 | C83: 911 | D83: 51 | E83: 34.6 | F83: 4.5 | H83: 45879 | I83: 0.5625 | J83: 27.84 | K83: =E83+T83 -> 36.468 | L83: =100*(22.1*10^6*10^((4.4-6.24*((J83+273.2)/1000)+9.95*((J83+273.2)/1000)^2-5.15*((J83+273.5)/1000)^3)*(1-647.3/(J83+273.2)))-101325*((K83-J83)/1514)*(1+J83/873))/(22.1*10^6*10^((4.4-6.24*((K83+273.2)/1000)+9.95*((K83+273.2)/1000)^2-5.15*((K83+273.5)/1000)^3)*(1-647.3/(K83+273.2)))) -> 51.53996 | M83: =U83 -> 722.8 | N83: =(0.408*AB83*(AE83-$Y$7)+$Y$6*($Y$6/(K83+273))*$Y$8*(Z83-AA83))/(AB83+$Y$6*(1+AC83*$Y$8)) -> 0.57556713 | Q83: 45879 | R83: 0.5625 | T83: 1.868 | U83: 722.8 | Z83: =0.6108*EXP(17.27*K83/(K83+237.3)) -> 6.0952569 | AA83: =(L83/100)*Z83 -> 3.141493 | AB83: =(4098*AA83)/((K83+237.3)^2) -> 0.17176817 | AC83: =IF(M83>10,0.24,0.96) -> 0.24 | AD83: =M83*3600/1000000 -> 2.60208 | AE83: =IF(M83>10,(1-$Y$4)*AD83,0) -> 2.0036016
A84: Bet Dagan Rad | B84: 10/08/2025 13:40 | C84: 907 | D84: 51 | E84: 34.6 | F84: 4 | H84: 45879 | I84: 0.56944444 | J84: 27.52 | K84: =E84+T84 -> 36.142 | L84: =100*(22.1*10^6*10^((4.4-6.24*((J84+273.2)/1000)+9.95*((J84+273.2)/1000)^2-5.15*((J84+273.5)/1000)^3)*(1-647.3/(J84+273.2)))-101325*((K84-J84)/1514)*(1+J84/873))/(22.1*10^6*10^((4.4-6.24*((K84+273.2)/1000)+9.95*((K84+273.2)/1000)^2-5.15*((K84+273.5)/1000)^3)*(1-647.3/(K84+273.2)))) -> 51.321293 | M84: =U84 -> 762.1 | N84: =(0.408*AB84*(AE84-$Y$7)+$Y$6*($Y$6/(K84+273))*$Y$8*(Z84-AA84))/(AB84+$Y$6*(1+AC84*$Y$8)) -> 0.60330384 | Q84: 45879 | R84: 0.56944444 | T84: 1.542 | U84: 762.1 | Z84: =0.6108*EXP(17.27*K84/(K84+237.3)) -> 5.9874412 | AA84: =(L84/100)*Z84 -> 3.0728323 | AB84: =(4098*AA84)/((K84+237.3)^2) -> 0.16841484 | AC84: =IF(M84>10,0.24,0.96) -> 0.24 | AD84: =M84*3600/1000000 -> 2.74356 | AE84: =IF(M84>10,(1-$Y$4)*AD84,0) -> 2.1125412
A85: Bet Dagan Rad | B85: 10/08/2025 13:50 | C85: 897 | D85: 50 | E85: 34.8 | F85: 4.4 | H85: 45879 | I85: 0.57638889 | J85: 27.72 | K85: =E85+T85 -> 36.162 | L85: =100*(22.1*10^6*10^((4.4-6.24*((J85+273.2)/1000)+9.95*((J85+273.2)/1000)^2-5.15*((J85+273.5)/1000)^3)*(1-647.3/(J85+273.2)))-101325*((K85-J85)/1514)*(1+J85/873))/(22.1*10^6*10^((4.4-6.24*((K85+273.2)/1000)+9.95*((K85+273.2)/1000)^2-5.15*((K85+273.5)/1000)^3)*(1-647.3/(K85+273.2)))) -> 52.192945 | M85: =U85 -> 709.7 | N85: =(0.408*AB85*(AE85-$Y$7)+$Y$6*($Y$6/(K85+273))*$Y$8*(Z85-AA85))/(AB85+$Y$6*(1+AC85*$Y$8)) -> 0.56481314 | Q85: 45879 | R85: 0.57638889 | T85: 1.362 | U85: 709.7 | Z85: =0.6108*EXP(17.27*K85/(K85+237.3)) -> 5.9940078 | AA85: =(L85/100)*Z85 -> 3.1284492 | AB85: =(4098*AA85)/((K85+237.3)^2) -> 0.171438 | AC85: =IF(M85>10,0.24,0.96) -> 0.24 | AD85: =M85*3600/1000000 -> 2.55492 | AE85: =IF(M85>10,(1-$Y$4)*AD85,0) -> 1.9672884
A86: Bet Dagan Rad | B86: 10/08/2025 14:00 | C86: 886 | D86: 50 | E86: 34.8 | F86: 4.3 | H86: 45879 | I86: 0.58333333 | J86: 27.6 | K86: =E86+T86 -> 36.192 | L86: =100*(22.1*10^6*10^((4.4-6.24*((J86+273.2)/1000)+9.95*((J86+273.2)/1000)^2-5.15*((J86+273.5)/1000)^3)*(1-647.3/(J86+273.2)))-101325*((K86-J86)/1514)*(1+J86/873))/(22.1*10^6*10^((4.4-6.24*((K86+273.2)/1000)+9.95*((K86+273.2)/1000)^2-5.15*((K86+273.5)/1000)^3)*(1-647.3/(K86+273.2)))) -> 51.501655 | M86: =U86 -> 688.2 | N86: =(0.408*AB86*(AE86-$Y$7)+$Y$6*($Y$6/(K86+273))*$Y$8*(Z86-AA86))/(AB86+$Y$6*(1+AC86*$Y$8)) -> 0.54576759 | Q86: 45879 | R86: 0.58333333 | T86: 1.392 | U86: 688.2 | Z86: =0.6108*EXP(17.27*K86/(K86+237.3)) -> 6.0038693 | AA86: =(L86/100)*Z86 -> 3.092092 | AB86: =(4098*AA86)/((K86+237.3)^2) -> 0.16940847 | AC86: =IF(M86>10,0.24,0.96) -> 0.24 | AD86: =M86*3600/1000000 -> 2.47752 | AE86: =IF(M86>10,(1-$Y$4)*AD86,0) -> 1.9076904
A87: Bet Dagan Rad | B87: 10/08/2025 14:10 | C87: 874 | D87: 51 | E87: 34.6 | F87: 3.6 | H87: 45879 | I87: 0.59027778 | J87: 27.32 | K87: =E87+T87 -> 35.724 | L87: =100*(22.1*10^6*10^((4.4-6.24*((J87+273.2)/1000)+9.95*((J87+273.2)/1000)^2-5.15*((J87+273.5)/1000)^3)*(1-647.3/(J87+273.2)))-101325*((K87-J87)/1514)*(1+J87/873))/(22.1*10^6*10^((4.4-6.24*((K87+273.2)/1000)+9.95*((K87+273.2)/1000)^2-5.15*((K87+273.5)/1000)^3)*(1-647.3/(K87+273.2)))) -> 52.044554 | M87: =U87 -> 672.7 | N87: =(0.408*AB87*(AE87-$Y$7)+$Y$6*($Y$6/(K87+273))*$Y$8*(Z87-AA87))/(AB87+$Y$6*(1+AC87*$Y$8)) -> 0.53159378 | Q87: 45879 | R87: 0.59027778 | T87: 1.124 | U87: 672.7 | Z87: =0.6108*EXP(17.27*K87/(K87+237.3)) -> 5.8516197 | AA87: =(L87/100)*Z87 -> 3.0454494 | AB87: =(4098*AA87)/((K87+237.3)^2) -> 0.16742553 | AC87: =IF(M87>10,0.24,0.96) -> 0.24 | AD87: =M87*3600/1000000 -> 2.42172 | AE87: =IF(M87>10,(1-$Y$4)*AD87,0) -> 1.8647244
...

Sheet Daily data
A1: Data | B1: T max (°C) | C1: T min (°C) | D1: T mean (°C) | E1: RH% max | F1: RH% min | G1: RH% mean | H1: Global Radiation daily integral, (MJ m⁻² day⁻¹) | I1: Eto (mm/day) P-M formula | J1: Eto (mm/day) Makkink formula
A2: {=INDEX('Clean Data_10min'!$H$2:$H$5688,1+144*(ROW()-2))} -> 45879 | B2: =_xlfn.MAXIFS('Clean Data_10min'!K:K, 'Clean Data_10min'!H:H, A2) -> 37.638 | C2: =_xlfn.MINIFS('Clean Data_10min'!K:K, 'Clean Data_10min'!H:H, A2) -> 25.095 | D2: =AVERAGEIFS('Clean Data_10min'!K:K, 'Clean Data_10min'!H:H, A2) -> 30.803708 | E2: =_xlfn.MAXIFS('Clean Data_10min'!L:L, 'Clean Data_10min'!H:H, A2) -> 84.22204 | F2: =_xlfn.MINIFS('Clean Data_10min'!L:L, 'Clean Data_10min'!H:H, A2) -> 31.675327 | G2: =AVERAGEIFS('Clean Data_10min'!L:L, 'Clean Data_10min'!H:H, A2) -> 61.875309 | H2: =SUMIFS('Clean Data_10min'!M:M, 'Clean Data_10min'!H:H, A2)*600/1000000 -> 16.865536 | I2: =(0.408*((4098*(0.6108*EXP(17.27*D2/(D2+237.3))))/((D2+237.3)^2))*((1-0.23)*H2) + 0.066*(900/(D2+273))*0.3*((0.6108*EXP(17.27*D2/(D2+237.3))) - (E2/100*(0.6108*EXP(17.27*D2/(D2+237.3))))) )/( ((4098*(0.6108*EXP(17.27*D2/(D2+237.3))))/((D2+237.3)^2)) + 0.066*(1+0.34*0.3)) -> 4.2425345 | J2: =0.75*( ((4098*(0.6108*EXP(17.27*D2/(D2+237.3))))/((D2+237.3)^2)) / ( ((4098*(0.6108*EXP(17.27*D2/(D2+237.3))))/((D2+237.3)^2)) + 0.066 ) ) *(H2/2.45) -> 4.0956767
A3: {=INDEX('Clean Data_10min'!$H$2:$H$5688,1+144*(ROW()-2))} -> 45880 | B3: =_xlfn.MAXIFS('Clean Data_10min'!K:K, 'Clean Data_10min'!H:H, A3) -> 38.476 | C3: =_xlfn.MINIFS('Clean Data_10min'!K:K, 'Clean Data_10min'!H:H, A3) -> 27.395 | D3: =AVERAGEIFS('Clean Data_10min'!K:K, 'Clean Data_10min'!H:H, A3) -> 31.587042 | E3: =_xlfn.MAXIFS('Clean Data_10min'!L:L, 'Clean Data_10min'!H:H, A3) -> 86.509309 | F3: =MIN(OFFSET('Clean Data_10min'!$L$2,(ROW()-ROW($F$2))*145, 0, 145, 1)) -> 33.831978 | G3: =AVERAGEIFS('Clean Data_10min'!L:L, 'Clean Data_10min'!H:H, A3) -> 63.696215 | H3: =SUMIFS('Clean Data_10min'!M:M, 'Clean Data_10min'!H:H, A3)*600/1000000 -> 16.214995 | I3: =(0.408*((4098*(0.6108*EXP(17.27*D3/(D3+237.3))))/((D3+237.3)^2))*((1-0.23)*H3) + 0.066*(900/(D3+273))*0.3*((0.6108*EXP(17.27*D3/(D3+237.3))) - (E3/100*(0.6108*EXP(17.27*D3/(D3+237.3))))) )/( ((4098*(0.6108*EXP(17.27*D3/(D3+237.3))))/((D3+237.3)^2)) + 0.066*(1+0.34*0.3)) -> 4.100548 | J3: =0.75*( ((4098*(0.6108*EXP(17.27*D3/(D3+237.3))))/((D3+237.3)^2)) / ( ((4098*(0.6108*EXP(17.27*D3/(D3+237.3))))/((D3+237.3)^2)) + 0.066 ) ) *(H3/2.45) -> 3.9688376
A4: {=INDEX('Clean Data_10min'!$H$2:$H$5688,1+144*(ROW()-2))} -> 45881 | B4: =_xlfn.MAXIFS('Clean Data_10min'!K:K, 'Clean Data_10min'!H:H, A4) -> 38.68 | C4: =_xlfn.MINIFS('Clean Data_10min'!K:K, 'Clean Data_10min'!H:H, A4) -> 26.6725 | D4: =AVERAGEIFS('Clean Data_10min'!K:K, 'Clean Data_10min'!H:H, A4) -> 31.802292 | E4: =_xlfn.MAXIFS('Clean Data_10min'!L:L, 'Clean Data_10min'!H:H, A4) -> 87.820736 | F4: =MIN(OFFSET('Clean Data_10min'!$L$2,(ROW()-ROW($F$2))*145, 0, 145, 1)) -> 47.424275 | G4: =AVERAGEIFS('Clean Data_10min'!L:L, 'Clean Data_10min'!H:H, A4) -> 72.098884 | H4: =SUMIFS('Clean Data_10min'!M:M, 'Clean Data_10min'!H:H, A4)*600/1000000 -> 14.782873 | I4: =(0.408*((4098*(0.6108*EXP(17.27*D4/(D4+237.3))))/((D4+237.3)^2))*((1-0.23)*H4) + 0.066*(900/(D4+273))*0.3*((0.6108*EXP(17.27*D4/(D4+237.3))) - (E4/100*(0.6108*EXP(17.27*D4/(D4+237.3))))) )/( ((4098*(0.6108*EXP(17.27*D4/(D4+237.3))))/((D4+237.3)^2)) + 0.066*(1+0.34*0.3)) -> 3.7460448 | J4: =0.75*( ((4098*(0.6108*EXP(17.27*D4/(D4+237.3))))/((D4+237.3)^2)) / ( ((4098*(0.6108*EXP(17.27*D4/(D4+237.3))))/((D4+237.3)^2)) + 0.066 ) ) *(H4/2.45) -> 3.6259632
A5: {=INDEX('Clean Data_10min'!$H$2:$H$5688,1+144*(ROW()-2))} -> 45882 | B5: =_xlfn.MAXIFS('Clean Data_10min'!K:K, 'Clean Data_10min'!H:H, A5) -> 38.49 | C5: =_xlfn.MINIFS('Clean Data_10min'!K:K, 'Clean Data_10min'!H:H, A5) -> 27.14 | D5: =AVERAGEIFS('Clean Data_10min'!K:K, 'Clean Data_10min'!H:H, A5) -> 32.429236 | E5: =_xlfn.MAXIFS('Clean Data_10min'!L:L, 'Clean Data_10min'!H:H, A5) -> 85.411061 | F5: =MIN(OFFSET('Clean Data_10min'!$L$2,(ROW()-ROW($F$2))*145, 0, 145, 1)) -> 53.581932 | G5: =AVERAGEIFS('Clean Data_10min'!L:L, 'Clean Data_10min'!H:H, A5) -> 71.480575 | H5: =SUMIFS('Clean Data_10min'!M:M, 'Clean Data_10min'!H:H, A5)*600/1000000 -> 16.128465 | I5: =(0.408*((4098*(0.6108*EXP(17.27*D5/(D5+237.3))))/((D5+237.3)^2))*((1-0.23)*H5) + 0.066*(900/(D5+273))*0.3*((0.6108*EXP(17.27*D5/(D5+237.3))) - (E5/100*(0.6108*EXP(17.27*D5/(D5+237.3))))) )/( ((4098*(0.6108*EXP(17.27*D5/(D5+237.3))))/((D5+237.3)^2)) + 0.066*(1+0.34*0.3)) -> 4.1246954 | J5: =0.75*( ((4098*(0.6108*EXP(17.27*D5/(D5+237.3))))/((D5+237.3)^2)) / ( ((4098*(0.6108*EXP(17.27*D5/(D5+237.3))))/((D5+237.3)^2)) + 0.066 ) ) *(H5/2.45) -> 3.9799602
A6: {=INDEX('Clean Data_10min'!$H$2:$H$5688,1+144*(ROW()-2))} -> 45883 | B6: =_xlfn.MAXIFS('Clean Data_10min'!K:K, 'Clean Data_10min'!H:H, A6) -> 39.7 | C6: =_xlfn.MINIFS('Clean Data_10min'!K:K, 'Clean Data_10min'!H:H, A6) -> 25.94 | D6: =AVERAGEIFS('Clean Data_10min'!K:K, 'Clean Data_10min'!H:H, A6) -> 31.584028 | E6: =_xlfn.MAXIFS('Clean Data_10min'!L:L, 'Clean Data_10min'!H:H, A6) -> 89.421285 | F6: =MIN(OFFSET('Clean Data_10min'!$L$2,(ROW()-ROW($F$2))*145, 0, 145, 1)) -> 44.518666 | G6: =AVERAGEIFS('Clean Data_10min'!L:L, 'Clean Data_10min'!H:H, A6) -> 71.864788 | H6: =SUMIFS('Clean Data_10min'!M:M, 'Clean Data_10min'!H:H, A6)*600/1000000 -> 17.895839 | I6: =(0.408*((4098*(0.6108*EXP(17.27*D6/(D6+237.3))))/((D6+237.3)^2))*((1-0.23)*H6) + 0.066*(900/(D6+273))*0.3*((0.6108*EXP(17.27*D6/(D6+237.3))) - (E6/100*(0.6108*EXP(17.27*D6/(D6+237.3))))) )/( ((4098*(0.6108*EXP(17.27*D6/(D6+237.3))))/((D6+237.3)^2)) + 0.066*(1+0.34*0.3)) -> 4.4906035 | J6: =0.75*( ((4098*(0.6108*EXP(17.27*D6/(D6+237.3))))/((D6+237.3)^2)) / ( ((4098*(0.6108*EXP(17.27*D6/(D6+237.3))))/((D6+237.3)^2)) + 0.066 ) ) *(H6/2.45) -> 4.3801165
A7: {=INDEX('Clean Data_10min'!$H$2:$H$5688,1+144*(ROW()-2))} -> 45884 | B7: =_xlfn.MAXIFS('Clean Data_10min'!K:K, 'Clean Data_10min'!H:H, A7) -> 39.83 | C7: =_xlfn.MINIFS('Clean Data_10min'!K:K, 'Clean Data_10min'!H:H, A7) -> 26.01 | D7: =AVERAGEIFS('Clean Data_10min'!K:K, 'Clean Data_10min'!H:H, A7) -> 31.459236 | E7: =_xlfn.MAXIFS('Clean Data_10min'!L:L, 'Clean Data_10min'!H:H, A7) -> 90.421191 | F7: =MIN(OFFSET('Clean Data_10min'!$L$2,(ROW()-ROW($F$2))*145, 0, 145, 1)) -> 36.635524 | G7: =AVERAGEIFS('Clean Data_10min'!L:L, 'Clean Data_10min'!H:H, A7) -> 66.579172 | H7: =SUMIFS('Clean Data_10min'!M:M, 'Clean Data_10min'!H:H, A7)*600/1000000 -> 19.050733 | I7: =(0.408*((4098*(0.6108*EXP(17.27*D7/(D7+237.3))))/((D7+237.3)^2))*((1-0.23)*H7) + 0.066*(900/(D7+273))*0.3*((0.6108*EXP(17.27*D7/(D7+237.3))) - (E7/100*(0.6108*EXP(17.27*D7/(D7+237.3))))) )/( ((4098*(0.6108*EXP(17.27*D7/(D7+237.3))))/((D7+237.3)^2)) + 0.066*(1+0.34*0.3)) -> 4.7603972 | J7: =0.75*( ((4098*(0.6108*EXP(17.27*D7/(D7+237.3))))/((D7+237.3)^2)) / ( ((4098*(0.6108*EXP(17.27*D7/(D7+237.3))))/((D7+237.3)^2)) + 0.066 ) ) *(H7/2.45) -> 4.6570261
A8: {=INDEX('Clean Data_10min'!$H$2:$H$5688,1+144*(ROW()-2))} -> 45885 | B8: =_xlfn.MAXIFS('Clean Data_10min'!K:K, 'Clean Data_10min'!H:H, A8) -> 36.27 | C8: =_xlfn.MINIFS('Clean Data_10min'!K:K, 'Clean Data_10min'!H:H, A8) -> 24.33 | D8: =AVERAGEIFS('Clean Data_10min'!K:K, 'Clean Data_10min'!H:H, A8) -> 29.730556 | E8: =_xlfn.MAXIFS('Clean Data_10min'!L:L, 'Clean Data_10min'!H:H, A8) -> 80.783395 | F8: =MIN(OFFSET('Clean Data_10min'!$L$2,(ROW()-ROW($F$2))*145, 0, 145, 1)) -> 50.908265 | G8: =AVERAGEIFS('Clean Data_10min'!L:L, 'Clean Data_10min'!H:H, A8) -> 66.937594 | H8: =SUMIFS('Clean Data_10min'!M:M, 'Clean Data_10min'!H:H, A8)*600/1000000 -> 18.736071 | I8: =(0.408*((4098*(0.6108*EXP(17.27*D8/(D8+237.3))))/((D8+237.3)^2))*((1-0.23)*H8) + 0.066*(900/(D8+273))*0.3*((0.6108*EXP(17.27*D8/(D8+237.3))) - (E8/100*(0.6108*EXP(17.27*D8/(D8+237.3))))) )/( ((4098*(0.6108*EXP(17.27*D8/(D8+237.3))))/((D8+237.3)^2)) + 0.066*(1+0.34*0.3)) -> 4.6687379 | J8: =0.75*( ((4098*(0.6108*EXP(17.27*D8/(D8+237.3))))/((D8+237.3)^2)) / ( ((4098*(0.6108*EXP(17.27*D8/(D8+237.3))))/((D8+237.3)^2)) + 0.066 ) ) *(H8/2.45) -> 4.4989028
A9: {=INDEX('Clean Data_10min'!$H$2:$H$5688,1+144*(ROW()-2))} -> 45886 | B9: =_xlfn.MAXIFS('Clean Data_10min'!K:K, 'Clean Data_10min'!H:H, A9) -> 34.8 | C9: =_xlfn.MINIFS('Clean Data_10min'!K:K, 'Clean Data_10min'!H:H, A9) -> 24.76 | D9: =AVERAGEIFS('Clean Data_10min'!K:K, 'Clean Data_10min'!H:H, A9) -> 29.981389 | E9: =_xlfn.MAXIFS('Clean Data_10min'!L:L, 'Clean Data_10min'!H:H, A9) -> 77.200331 | F9: =MIN(OFFSET('Clean Data_10min'!$L$2,(ROW()-ROW($F$2))*145, 0, 145, 1)) -> 48.392046 | G9: =AVERAGEIFS('Clean Data_10min'!L:L, 'Clean Data_10min'!H:H, A9) -> 61.877715 | H9: =SUMIFS('Clean Data_10min'!M:M, 'Clean Data_10min'!H:H, A9)*600/1000000 -> 18.267234 | I9: =(0.408*((4098*(0.6108*EXP(17.27*D9/(D9+237.3))))/((D9+237.3)^2))*((1-0.23)*H9) + 0.066*(900/(D9+273))*0.3*((0.6108*EXP(17.27*D9/(D9+237.3))) - (E9/100*(0.6108*EXP(17.27*D9/(D9+237.3))))) )/( ((4098*(0.6108*EXP(17.27*D9/(D9+237.3))))/((D9+237.3)^2)) + 0.066*(1+0.34*0.3)) -> 4.59735 | J9: =0.75*( ((4098*(0.6108*EXP(17.27*D9/(D9+237.3))))/((D9+237.3)^2)) / ( ((4098*(0.6108*EXP(17.27*D9/(D9+237.3))))/((D9+237.3)^2)) + 0.066 ) ) *(H9/2.45) -> 4.3981288
A10: {=INDEX('Clean Data_10min'!$H$2:$H$5688,1+144*(ROW()-2))} -> 45887 | B10: =_xlfn.MAXIFS('Clean Data_10min'!K:K, 'Clean Data_10min'!H:H, A10) -> 34.7625 | C10: =_xlfn.MINIFS('Clean Data_10min'!K:K, 'Clean Data_10min'!H:H, A10) -> 25.02 | D10: =AVERAGEIFS('Clean Data_10min'!K:K, 'Clean Data_10min'!H:H, A10) -> 29.39217 | E10: =_xlfn.MAXIFS('Clean Data_10min'!L:L, 'Clean Data_10min'!H:H, A10) -> 87.218111 | F10: =MIN(OFFSET('Clean Data_10min'!$L$2,(ROW()-ROW($F$2))*145, 0, 145, 1)) -> 51.131191 | G10: =AVERAGEIFS('Clean Data_10min'!L:L, 'Clean Data_10min'!H:H, A10) -> 70.717498 | H10: =SUMIFS('Clean Data_10min'!M:M, 'Clean Data_10min'!H:H, A10)*600/1000000 -> 18.858464 | I10: =(0.408*((4098*(0.6108*EXP(17.27*D10/(D10+237.3))))/((D10+237.3)^2))*((1-0.23)*H10) + 0.066*(900/(D10+273))*0.3*((0.6108*EXP(17.27*D10/(D10+237.3))) - (E10/100*(0.6108*EXP(17.27*D10/(D10+237.3))))) )/( ((4098*(0.6108*EXP(17.27*D10/(D10+237.3))))/((D10+237.3)^2)) + 0.066*(1+0.34*0.3)) -> 4.6291398 | J10: =0.75*( ((4098*(0.6108*EXP(17.27*D10/(D10+237.3))))/((D10+237.3)^2)) / ( ((4098*(0.6108*EXP(17.27*D10/(D10+237.3))))/((D10+237.3)^2)) + 0.066 ) ) *(H10/2.45) -> 4.511676
A11: {=INDEX('Clean Data_10min'!$H$2:$H$5688,1+144*(ROW()-2))} -> 45888 | B11: =_xlfn.MAXIFS('Clean Data_10min'!K:K, 'Clean Data_10min'!H:H, A11) -> 35.12 | C11: =_xlfn.MINIFS('Clean Data_10min'!K:K, 'Clean Data_10min'!H:H, A11) -> 22.72 | D11: =AVERAGEIFS('Clean Data_10min'!K:K, 'Clean Data_10min'!H:H, A11) -> 28.697483 | E11: =_xlfn.MAXIFS('Clean Data_10min'!L:L, 'Clean Data_10min'!H:H, A11) -> 83.211824 | F11: =MIN(OFFSET('Clean Data_10min'!$L$2,(ROW()-ROW($F$2))*145, 0, 145, 1)) -> 53.113622 | G11: =AVERAGEIFS('Clean Data_10min'!L:L, 'Clean Data_10min'!H:H, A11) -> 69.304495 | H11: =SUMIFS('Clean Data_10min'!M:M, 'Clean Data_10min'!H:H, A11)*600/1000000 -> 18.250678 | I11: =(0.408*((4098*(0.6108*EXP(17.27*D11/(D11+237.3))))/((D11+237.3)^2))*((1-0.23)*H11) + 0.066*(900/(D11+273))*0.3*((0.6108*EXP(17.27*D11/(D11+237.3))) - (E11/100*(0.6108*EXP(17.27*D11/(D11+237.3))))) )/( ((4098*(0.6108*EXP(17.27*D11/(D11+237.3))))/((D11+237.3)^2)) + 0.066*(1+0.34*0.3)) -> 4.4766481 | J11: =0.75*( ((4098*(0.6108*EXP(17.27*D11/(D11+237.3))))/((D11+237.3)^2)) / ( ((4098*(0.6108*EXP(17.27*D11/(D11+237.3))))/((D11+237.3)^2)) + 0.066 ) ) *(H11/2.45) -> 4.3326343
A12: {=INDEX('Clean Data_10min'!$H$2:$H$5688,1+144*(ROW()-2))} -> 45889 | B12: =_xlfn.MAXIFS('Clean Data_10min'!K:K, 'Clean Data_10min'!H:H, A12) -> 35.82 | C12: =_xlfn.MINIFS('Clean Data_10min'!K:K, 'Clean Data_10min'!H:H, A12) -> 22.6825 | D12: =AVERAGEIFS('Clean Data_10min'!K:K, 'Clean Data_10min'!H:H, A12) -> 29.060556 | E12: =_xlfn.MAXIFS('Clean Data_10min'!L:L, 'Clean Data_10min'!H:H, A12) -> 86.161224 | F12: =MIN(OFFSET('Clean Data_10min'!$L$2,(ROW()-ROW($F$2))*145, 0, 145, 1)) -> 50.60745 | G12: =AVERAGEIFS('Clean Data_10min'!L:L, 'Clean Data_10min'!H:H, A12) -> 70.394713 | H12: =SUMIFS('Clean Data_10min'!M:M, 'Clean Data_10min'!H:H, A12)*600/1000000 -> 17.228117 | I12: =(0.408*((4098*(0.6108*EXP(17.27*D12/(D12+237.3))))/((D12+237.3)^2))*((1-0.23)*H12) + 0.066*(900/(D12+273))*0.3*((0.6108*EXP(17.27*D12/(D12+237.3))) - (E12/100*(0.6108*EXP(17.27*D12/(D12+237.3))))) )/( ((4098*(0.6108*EXP(17.27*D12/(D12+237.3))))/((D12+237.3)^2)) + 0.066*(1+0.34*0.3)) -> 4.2289807 | J12: =0.75*( ((4098*(0.6108*EXP(17.27*D12/(D12+237.3))))/((D12+237.3)^2)) / ( ((4098*(0.6108*EXP(17.27*D12/(D12+237.3))))/((D12+237.3)^2)) + 0.066 ) ) *(H12/2.45) -> 4.1065764
A13: {=INDEX('Clean Data_10min'!$H$2:$H$5688,1+144*(ROW()-2))} -> 45890 | B13: =_xlfn.MAXIFS('Clean Data_10min'!K:K, 'Clean Data_10min'!H:H, A13) -> 35.338 | C13: =_xlfn.MINIFS('Clean Data_10min'!K:K, 'Clean Data_10min'!H:H, A13) -> 25.005 | D13: =AVERAGEIFS('Clean Data_10min'!K:K, 'Clean Data_10min'!H:H, A13) -> 29.534264 | E13: =_xlfn.MAXIFS('Clean Data_10min'!L:L, 'Clean Data_10min'!H:H, A13) -> 88.272056 | F13: =MIN(OFFSET('Clean Data_10min'!$L$2,(ROW()-ROW($F$2))*145, 0, 145, 1)) -> 50.699214 | G13: =AVERAGEIFS('Clean Data_10min'!L:L, 'Clean Data_10min'!H:H, A13) -> 69.724479 | H13: =SUMIFS('Clean Data_10min'!M:M, 'Clean Data_10min'!H:H, A13)*600/1000000 -> 16.676297 | I13: =(0.408*((4098*(0.6108*EXP(17.27*D13/(D13+237.3))))/((D13+237.3)^2))*((1-0.23)*H13) + 0.066*(900/(D13+273))*0.3*((0.6108*EXP(17.27*D13/(D13+237.3))) - (E13/100*(0.6108*EXP(17.27*D13/(D13+237.3))))) )/( ((4098*(0.6108*EXP(17.27*D13/(D13+237.3))))/((D13+237.3)^2)) + 0.066*(1+0.34*0.3)) -> 4.1037221 | J13: =0.75*( ((4098*(0.6108*EXP(17.27*D13/(D13+237.3))))/((D13+237.3)^2)) / ( ((4098*(0.6108*EXP(17.27*D13/(D13+237.3))))/((D13+237.3)^2)) + 0.066 ) ) *(H13/2.45) -> 3.995809
